<sdf version="1.6">
    <model name="legs_with_muscles_simplified">
        <link name="hip">
            <pose frame="">0 0 0 0 -0 0</pose>
            <inertial>
                <pose frame="">0.176733 0.853744 -0.015868 0 -0 0</pose>
                <mass>1.51173</mass>
                <inertia>
                    <ixx>0.00636164</ixx>
                    <ixy>-0.00042263</ixy>
                    <ixz>-8.74403e-05</ixz>
                    <iyy>0.0238516</iyy>
                    <iyz>-0.000322312</iyz>
                    <izz>0.0224549</izz>
                </inertia>
            </inertial>
            <collision name="hip_collision">
                <pose frame="">0 0 0 0 -0 0</pose>
                <geometry>
                    <mesh>
                        <scale>1 1 1</scale>
                        <uri>model://legs_with_muscles_simplified/cad/hip.STL</uri>
                    </mesh>
                </geometry>
            </collision>
            <visual name="hip_visual">
                <pose frame="">0 0 0 0 -0 0</pose>
                <geometry>
                    <mesh>
                        <scale>1 1 1</scale>
                        <uri>model://legs_with_muscles_simplified/cad/hip.STL</uri>
                    </mesh>
                </geometry>
                <plugin filename="libtendon_visualizer.so" name="tendon_visualizer" />
            </visual>
        </link>
        <link name="thigh_left">
            <pose frame="">0 0.03811 0.8076 1.64067 0 -3.14159</pose>
            <inertial>
                <pose frame="">0.034035 -0.438627 0.013194 0 -0 0</pose>
                <mass>2.13431</mass>
                <inertia>
                    <ixx>0.110994</ixx>
                    <ixy>0.000263516</ixy>
                    <ixz>-0.000122665</ixz>
                    <iyy>0.00433246</iyy>
                    <iyz>0.00925393</iyz>
                    <izz>0.108215</izz>
                </inertia>
            </inertial>
            <collision name="thigh_left_collision">
                <pose frame="">0 0 0 0 -0 0</pose>
                <geometry>
                    <mesh>
                        <scale>1 1 1</scale>
                        <uri>model://legs_with_muscles_simplified/cad/thigh_left.STL</uri>
                    </mesh>
                </geometry>
            </collision>
            <visual name="thigh_left_visual">
                <pose frame="">0 0 0 0 0 0</pose>
                <geometry>
                    <mesh>
                        <scale>1 1 1</scale>
                        <uri>model://legs_with_muscles_simplified/cad/thigh_left.STL</uri>
                    </mesh>
                </geometry>
            </visual>
        </link>
        <link name="shank_left">
            <pose frame="">0 0.03811 0.8076 1.64067 0 -3.14159</pose>
            <inertial>
                <pose frame="">0.034035 -0.438627 0.013194 0 -0 0</pose>
                <mass>2.13431</mass>
                <inertia>
                    <ixx>0.110994</ixx>
                    <ixy>0.000263516</ixy>
                    <ixz>-0.000122665</ixz>
                    <iyy>0.00433246</iyy>
                    <iyz>0.00925393</iyz>
                    <izz>0.108215</izz>
                </inertia>
            </inertial>
            <collision name="shank_left_collision">
                <pose frame="">0.04646 -0.427589 -0.003263 -3.02635 -0 -3.14159</pose>
                <geometry>
                    <mesh>
                        <scale>1 1 1</scale>
                        <uri>model://legs_with_muscles_simplified/cad/shank_left.STL</uri>
                    </mesh>
                </geometry>
            </collision>
            <visual name="shank_left_visual">
                <pose frame="">0.04646 -0.427589 -0.003263 -3.02635 -0 -3.14159</pose>
                <geometry>
                    <mesh>
                        <scale>1 1 1</scale>
                        <uri>model://legs_with_muscles_simplified/cad/shank_left.STL</uri>
                    </mesh>
                </geometry>
            </visual>
        </link>

        <link name="foot_left">
            <pose frame="">0 0.03811 0.8076 1.64067 0 -3.14159</pose>
            <inertial>
                <pose frame="">0.034035 -0.438627 0.013194 0 -0 0</pose>
                <mass>2.13431</mass>
                <inertia>
                    <ixx>0.110994</ixx>
                    <ixy>0.000263516</ixy>
                    <ixz>-0.000122665</ixz>
                    <iyy>0.00433246</iyy>
                    <iyz>0.00925393</iyz>
                    <izz>0.108215</izz>
                </inertia>
            </inertial>
            <collision name="foot_left_collision">
                <pose frame="">0.04646 -0.780611 0.035455 -3.07171 -0 -3.14159</pose>
                <geometry>
                    <mesh>
                        <scale>1 1 1</scale>
                        <uri>model://legs_with_muscles_simplified/cad/foot_left.STL</uri>
                    </mesh>
                </geometry>
            </collision>
            <visual name="foot_left_visual">
                <pose frame="">0.04646 -0.780611 0.035455 -3.07171 -0 -3.14159</pose>
                <geometry>
                    <mesh>
                        <scale>1 1 1</scale>
                        <uri>model://legs_with_muscles_simplified/cad/foot_left.STL</uri>
                    </mesh>
                </geometry>
            </visual>
        </link>

        <link name="thigh_right">
            <pose frame="">0.230814 0.03811 0.8076 1.46218 -0 0</pose>
            <inertial>
                <pose frame="">0.125114 -0.410563 -0.005059 0 -0 0</pose>
                <mass>1.98546</mass>
                <inertia>
                    <ixx>0.0867897</ixx>
                    <ixy>0.000370501</ixy>
                    <ixz>2.8593e-05</ixz>
                    <iyy>0.0028388</iyy>
                    <iyz>-0.00246663</iyz>
                    <izz>0.0853608</izz>
                </inertia>
            </inertial>
            <collision name="thigh_right_collision">
                <pose frame="">0 0 0 0 -0 0</pose>
                <geometry>
                    <mesh>
                        <scale>1 1 1</scale>
                        <uri>model://legs_with_muscles_simplified/cad/thigh_right.STL</uri>
                    </mesh>
                </geometry>
            </collision>
            <visual name="thigh_right_visual">
                <pose frame="">0 0 0 0 -0 0</pose>
                <geometry>
                    <mesh>
                        <scale>1 1 1</scale>
                        <uri>model://legs_with_muscles_simplified/cad/thigh_right.STL</uri>
                    </mesh>
                </geometry>
            </visual>
        </link>

        <link name="shank_right">
            <pose frame="">0.230814 0.03811 0.8076 1.46218 -0 0</pose>
            <inertial>
                <pose frame="">0.125114 -0.410563 -0.005059 0 -0 0</pose>
                <mass>1.98546</mass>
                <inertia>
                    <ixx>0.0867897</ixx>
                    <ixy>0.000370501</ixy>
                    <ixz>2.8593e-05</ixz>
                    <iyy>0.0028388</iyy>
                    <iyz>-0.00246663</iyz>
                    <izz>0.0853608</izz>
                </inertia>
            </inertial>
            <collision name="shank_right_collision">
                <pose frame="">0.119726 -0.427589 -0.003263 0.014989 -0 0</pose>
                <geometry>
                    <mesh>
                        <scale>1 1 1</scale>
                        <uri>model://legs_with_muscles_simplified/cad/shank_right.STL</uri>
                    </mesh>
                </geometry>
            </collision>
            <visual name="shank_right_visual">
                <pose frame="">0.119726 -0.427589 -0.003263 0.014989 -0 0</pose>
                <geometry>
                    <mesh>
                        <scale>1 1 1</scale>
                        <uri>model://legs_with_muscles_simplified/cad/shank_right.STL</uri>
                    </mesh>
                </geometry>
            </visual>
        </link>

        <link name="foot_right">
            <pose frame="">0.230814 0.03811 0.8076 1.46218 -0 0</pose>
            <inertial>
                <pose frame="">0.125114 -0.410563 -0.005059 0 -0 0</pose>
                <mass>1.98546</mass>
                <inertia>
                    <ixx>0.0867897</ixx>
                    <ixy>0.000370501</ixy>
                    <ixz>2.8593e-05</ixz>
                    <iyy>0.0028388</iyy>
                    <iyz>-0.00246663</iyz>
                    <izz>0.0853608</izz>
                </inertia>
            </inertial>
            <collision name="foot_right_collision">
                <pose frame="">0.119726 -0.782543 -0.003646 -0.090258 0 0</pose>
                <geometry>
                    <mesh>
                        <scale>1 1 1</scale>
                        <uri>model://legs_with_muscles_simplified/cad/foot_right.STL</uri>
                    </mesh>
                </geometry>
            </collision>
            <visual name="tfoot_right_visual">
                <pose frame="">0.119726 -0.782543 -0.003646 -0.090258 0 0</pose>
                <geometry>
                    <mesh>
                        <scale>1 1 1</scale>
                        <uri>model://legs_with_muscles_simplified/cad/foot_right.STL</uri>
                    </mesh>
                </geometry>
            </visual>
        </link>

        

        <joint name="motor0" type="revolute">
            <parent>hip</parent>
            <child>thigh_left</child>
            <axis>
                <xyz>-1 -0 0</xyz>
                <limit>
                    <lower>-1e+16</lower>
                    <upper>1e+16</upper>
                </limit>
                <dynamics>
                    <spring_reference>0</spring_reference>
                    <spring_stiffness>0</spring_stiffness>
                </dynamics>
                <use_parent_model_frame>1</use_parent_model_frame>
            </axis>
        </joint>

        <joint name="motor1" type="revolute">
            <parent>hip</parent>
            <child>thigh_left</child>
            <axis>
                <xyz>-1 -0 0</xyz>
                <limit>
                    <lower>-1e+16</lower>
                    <upper>1e+16</upper>
                </limit>
                <dynamics>
                    <spring_reference>0</spring_reference>
                    <spring_stiffness>0</spring_stiffness>
                </dynamics>
                <use_parent_model_frame>1</use_parent_model_frame>
            </axis>
        </joint>

        <joint name="motor2" type="revolute">
            <parent>hip</parent>
            <child>thigh_left</child>
            <axis>
                <xyz>-1 -0 0</xyz>
                <limit>
                    <lower>-1e+16</lower>
                    <upper>1e+16</upper>
                </limit>
                <dynamics>
                    <spring_reference>0</spring_reference>
                    <spring_stiffness>0</spring_stiffness>
                </dynamics>
                <use_parent_model_frame>1</use_parent_model_frame>
            </axis>
        </joint>

        <joint name="motor3" type="revolute">
            <parent>hip</parent>
            <child>thigh_left</child>
            <axis>
                <xyz>-1 -0 0</xyz>
                <limit>
                    <lower>-1e+16</lower>
                    <upper>1e+16</upper>
                </limit>
                <dynamics>
                    <spring_reference>0</spring_reference>
                    <spring_stiffness>0</spring_stiffness>
                </dynamics>
                <use_parent_model_frame>1</use_parent_model_frame>
            </axis>
        </joint>

        <joint name="motor4" type="revolute">
            <parent>thigh_left</parent>
            <child>shank_left</child>
            <axis>
                <xyz>-1 -0 0</xyz>
                <limit>
                    <lower>-1e+16</lower>
                    <upper>1e+16</upper>
                </limit>
                <dynamics>
                    <spring_reference>0</spring_reference>
                    <spring_stiffness>0</spring_stiffness>
                </dynamics>
                <use_parent_model_frame>1</use_parent_model_frame>
            </axis>
        </joint>

        <joint name="motor5" type="revolute">
            <parent>thigh_left</parent>
            <child>shank_left</child>
            <axis>
                <xyz>-1 -0 0</xyz>
                <limit>
                    <lower>-1e+16</lower>
                    <upper>1e+16</upper>
                </limit>
                <dynamics>
                    <spring_reference>0</spring_reference>
                    <spring_stiffness>0</spring_stiffness>
                </dynamics>
                <use_parent_model_frame>1</use_parent_model_frame>
            </axis>
        </joint>

        <joint name="motor6" type="revolute">
            <parent>shank_left</parent>
            <child>foot_left</child>
            <axis>
                <xyz>-1 -0 0</xyz>
                <limit>
                    <lower>-1e+16</lower>
                    <upper>1e+16</upper>
                </limit>
                <dynamics>
                    <spring_reference>0</spring_reference>
                    <spring_stiffness>0</spring_stiffness>
                </dynamics>
                <use_parent_model_frame>1</use_parent_model_frame>
            </axis>
        </joint>

        <joint name="motor7" type="revolute">
            <parent>shank_left</parent>
            <child>foot_left</child>
            <axis>
                <xyz>-1 -0 0</xyz>
                <limit>
                    <lower>-1e+16</lower>
                    <upper>1e+16</upper>
                </limit>
                <dynamics>
                    <spring_reference>0</spring_reference>
                    <spring_stiffness>0</spring_stiffness>
                </dynamics>
                <use_parent_model_frame>1</use_parent_model_frame>
            </axis>
        </joint>

        

        <joint name="motor8" type="revolute">
            <parent>hip</parent>
            <child>thigh_right</child>
            <axis>
                <xyz>-1 -0 0</xyz>
                <limit>
                    <lower>-1e+16</lower>
                    <upper>1e+16</upper>
                </limit>
                <dynamics>
                    <spring_reference>0</spring_reference>
                    <spring_stiffness>0</spring_stiffness>
                </dynamics>
                <use_parent_model_frame>1</use_parent_model_frame>
            </axis>
        </joint>

        <joint name="motor9" type="revolute">
            <parent>hip</parent>
            <child>thigh_right</child>
            <axis>
                <xyz>-1 -0 0</xyz>
                <limit>
                    <lower>-1e+16</lower>
                    <upper>1e+16</upper>
                </limit>
                <dynamics>
                    <spring_reference>0</spring_reference>
                    <spring_stiffness>0</spring_stiffness>
                </dynamics>
                <use_parent_model_frame>1</use_parent_model_frame>
            </axis>
        </joint>

        <joint name="motor10" type="revolute">
            <parent>hip</parent>
            <child>thigh_right</child>
            <axis>
                <xyz>-1 -0 0</xyz>
                <limit>
                    <lower>-1e+16</lower>
                    <upper>1e+16</upper>
                </limit>
                <dynamics>
                    <spring_reference>0</spring_reference>
                    <spring_stiffness>0</spring_stiffness>
                </dynamics>
                <use_parent_model_frame>1</use_parent_model_frame>
            </axis>
        </joint>

        <joint name="motor11" type="revolute">
            <parent>hip</parent>
            <child>thigh_right</child>
            <axis>
                <xyz>-1 -0 0</xyz>
                <limit>
                    <lower>-1e+16</lower>
                    <upper>1e+16</upper>
                </limit>
                <dynamics>
                    <spring_reference>0</spring_reference>
                    <spring_stiffness>0</spring_stiffness>
                </dynamics>
                <use_parent_model_frame>1</use_parent_model_frame>
            </axis>
        </joint>

        <joint name="motor12" type="revolute">
            <parent>thigh_right</parent>
            <child>shank_right</child>
            <axis>
                <xyz>-1 -0 0</xyz>
                <limit>
                    <lower>-1e+16</lower>
                    <upper>1e+16</upper>
                </limit>
                <dynamics>
                    <spring_reference>0</spring_reference>
                    <spring_stiffness>0</spring_stiffness>
                </dynamics>
                <use_parent_model_frame>1</use_parent_model_frame>
            </axis>
        </joint>

        <joint name="motor13" type="revolute">
            <parent>thigh_right</parent>
            <child>shank_right</child>
            <axis>
                <xyz>-1 -0 0</xyz>
                <limit>
                    <lower>-1e+16</lower>
                    <upper>1e+16</upper>
                </limit>
                <dynamics>
                    <spring_reference>0</spring_reference>
                    <spring_stiffness>0</spring_stiffness>
                </dynamics>
                <use_parent_model_frame>1</use_parent_model_frame>
            </axis>
        </joint>

        <joint name="motor14" type="revolute">
            <parent>shank_right</parent>
            <child>foot_right</child>
            <axis>
                <xyz>-1 -0 0</xyz>
                <limit>
                    <lower>-1e+16</lower>
                    <upper>1e+16</upper>
                </limit>
                <dynamics>
                    <spring_reference>0</spring_reference>
                    <spring_stiffness>0</spring_stiffness>
                </dynamics>
                <use_parent_model_frame>1</use_parent_model_frame>
            </axis>
        </joint>

        <joint name="motor15" type="revolute">
            <parent>shank_right</parent>
            <child>foot_right</child>
            <axis>
                <xyz>-1 -0 0</xyz>
                <limit>
                    <lower>-1e+16</lower>
                    <upper>1e+16</upper>
                </limit>
                <dynamics>
                    <spring_reference>0</spring_reference>
                    <spring_stiffness>0</spring_stiffness>
                </dynamics>
                <use_parent_model_frame>1</use_parent_model_frame>
            </axis>
        </joint>

        <joint name="fixtoworld" type="prismatic">
            <pose>0 0 0 0 0 0</pose>
            <child>hip</child>
            <parent>world</parent>
            <axis>
                <limit>
                    <lower>0.0</lower>
                    <upper>0.0</upper>
                </limit>
                <xyz>0 0 1</xyz>
            </axis>
        </joint>

        <plugin filename="libroboySim.so" name="roboySim">
            <myoMuscle name="motor0">
                <link name="hip">
                    <viaPoint>-0.023465 0.079022 0.881308</viaPoint>
                </link>
                <link name="thigh_left">
                    <viaPoint>0.072869 -0.306333 0.000250</viaPoint>
                </link>
            </myoMuscle>

            <myoMuscle name="motor1">
                <link name="hip">
                    <viaPoint>-0.069702 0.029671 0.893051</viaPoint>
                </link>
                <link name="thigh_left">
                    <viaPoint>0.072869 -0.306333 0.000250</viaPoint>
                </link>
            </myoMuscle>

            <myoMuscle name="motor2">
                <link name="hip">
                    <viaPoint>-0.024795 -0.015988 0.855847</viaPoint>
                </link>
                <link name="thigh_left">
                    <viaPoint>0.072869 -0.306333 0.000250</viaPoint>
                </link>
            </myoMuscle>

            <myoMuscle name="motor3">
                <link name="thigh_left">
                    <viaPoint>-0.015053 -0.106513 -0.001072</viaPoint>
                </link>
                <link name="hip">
                    <viaPoint>0.135232 -0.008528 0.764690</viaPoint>
                </link>
            </myoMuscle>

            <!--<myoMuscle name="motor4">-->
                <!--<link name="thigh_left">-->
                    <!--<viaPoint>0.037461 -0.330196 0.033621</viaPoint>-->
                <!--</link>-->
                <!--<link name="shank_left">-->
                    <!--<viaPoint>0.008113 -0.039850 0.025255</viaPoint>-->
                <!--</link>-->
            <!--</myoMuscle>-->

            <!--<myoMuscle name="motor5">-->
                <!--<link name="thigh_left">-->
                    <!--<viaPoint>0.038179 -0.328687 -0.034989</viaPoint>-->
                <!--</link>-->
                <!--<link name="shank_left">-->
                    <!--<viaPoint>0.009177 -0.041479 -0.025091</viaPoint>-->
                <!--</link>-->
            <!--</myoMuscle>-->

            <!--<myoMuscle name="motor6">-->
                <!--<link name="shank_left">-->
                    <!--<viaPoint>0.008307 -0.226060 0.031391</viaPoint>-->
                <!--</link>-->
                <!--<link name="foot_left">-->
                    <!--<viaPoint>0.011353 0.022718 -0.043631</viaPoint>-->
                <!--</link>-->
            <!--</myoMuscle>-->

            <!--<myoMuscle name="motor7">-->
                <!--<link name="shank_left">-->
                    <!--<viaPoint>0.011125 -0.223381 -0.032644</viaPoint>-->
                <!--</link>-->
                <!--<link name="foot_left">-->
                    <!--<viaPoint>0.010537 0.022572 0.043640</viaPoint>-->
                <!--</link>-->
            <!--</myoMuscle>-->

            <!--<myoMuscle name="motor8">-->
                <!--<link name="hip">-->
                    <!--<viaPoint>0.346031 0.079086 0.880833</viaPoint>-->
                <!--</link>-->
                <!--<link name="thigh_right">-->
                    <!--<viaPoint>0.162775 -0.305707 0.000590</viaPoint>-->
                <!--</link>-->
            <!--</myoMuscle>-->

            <!--<myoMuscle name="motor9">-->
                <!--<link name="hip">-->
                    <!--<viaPoint>0.390408 0.028832 0.895399</viaPoint>-->
                <!--</link>-->
                <!--<link name="thigh_right">-->
                    <!--<viaPoint>0.162775 -0.305707 0.000590</viaPoint>-->
                <!--</link>-->
            <!--</myoMuscle>-->

            <!--<myoMuscle name="motor10">-->
                <!--<link name="hip">-->
                    <!--<viaPoint>0.348198 -0.015541 0.857039</viaPoint>-->
                <!--</link>-->
                <!--<link name="thigh_right">-->
                    <!--<viaPoint>0.162775 -0.305707 0.000590</viaPoint>-->
                <!--</link>-->
            <!--</myoMuscle>-->

            <!--<myoMuscle name="motor11">-->
                <!--<link name="hip">-->
                    <!--<viaPoint>0.238571 -0.002497 0.764879</viaPoint>-->
                <!--</link>-->
                <!--<link name="thigh_right">-->
                    <!--<viaPoint>0.078886 -0.104261 0.008974</viaPoint>-->
                <!--</link>-->
            <!--</myoMuscle>-->

            <!--<myoMuscle name="motor12">-->
                <!--<link name="thigh_right">-->
                    <!--<viaPoint>0.129368 -0.330507 0.033731</viaPoint>-->
                <!--</link>-->
                <!--<link name="shank_right">-->
                    <!--<viaPoint>0.005045 -0.041918 0.025074</viaPoint>-->
                <!--</link>-->
            <!--</myoMuscle>-->

            <!--<myoMuscle name="motor13">-->
                <!--<link name="thigh_right">-->
                    <!--<viaPoint>0.129066 -0.330739 -0.034967</viaPoint>-->
                <!--</link>-->
                <!--<link name="shank_right">-->
                    <!--<viaPoint>0.009385 -0.042415 -0.025388</viaPoint>-->
                <!--</link>-->
            <!--</myoMuscle>-->

            <!--<myoMuscle name="motor14">-->
                <!--<link name="shank_right">-->
                    <!--<viaPoint>0.009415 -0.224921 0.032228</viaPoint>-->
                <!--</link>-->
                <!--<link name="foot_right">-->
                    <!--<viaPoint>0.011691 0.023231 -0.042039</viaPoint>-->
                <!--</link>-->
            <!--</myoMuscle>-->

            <!--<myoMuscle name="motor15">-->
                <!--<link name="shank_right">-->
                    <!--<viaPoint>0.010165 -0.224802 -0.032358</viaPoint>-->
                <!--</link>-->
                <!--<link name="foot_right">-->
                    <!--<viaPoint>0.010031 0.023839 0.043937</viaPoint>-->
                <!--</link>-->
            <!--</myoMuscle>-->
        </plugin>
    </model>
</sdf>