<?xml version="1.0" ?>
<robot name="arm">
    <joint name="motor0" type="revolute">
        <parent link="arm__upper_arm"/>
        <child link="arm__hand"/>
        <origin rpy="0.64864 -1.56979 -2.21944" xyz="-0.02301 -0.19499 -0.51016"/>
        <axis xyz="0  1  0"/>
        <limit effort="0.0" lower="-0.7" upper="1.57" velocity="0.0"/>
    </joint>
    <joint name="motor1" type="fixed">
        <parent link="arm__arm_holder"/>
        <child link="arm__upper_arm"/>
        <origin rpy="1.57    0      1.5707" xyz="0.50001  0.21995  0.53039"/>
        <axis xyz="0  1  0"/>
        <limit effort="0.0" lower="0.0" upper="0.0" velocity="0.0"/>
    </joint>
    <link name="arm__arm_holder">
        <inertial>
            <mass value="2"/>
            <origin rpy="0  0  0" xyz="0    0.31  0.3"/>
            <inertia ixx="1" ixy="0" ixz="0" iyy="1" iyz="0" izz="1"/>
        </inertial>
        <collision name="arm__collision">
            <origin rpy="0  0  0" xyz="0    0.31  0.3"/>
            <geometry>
                <box size=".1 .1 .5"/>
            </geometry>
        </collision>
        <visual name="arm__visual">
            <origin rpy="0  0  0" xyz="0    0.31  0.3"/>
            <geometry>
                <box size=".1 .1 .5"/>
            </geometry>
        </visual>
    </link>
    <link name="arm__hand">
        <inertial>
            <mass value="5"/>
            <origin rpy="0    0   -1.57" xyz="1.50000000e-01   1.10000000e-04   0.00000000e+00"/>
            <inertia ixx="1" ixy="0" ixz="0" iyy="1" iyz="0" izz="1"/>
        </inertial>
        <collision name="arm__collision">
            <origin rpy="0    0   -1.57" xyz="1.50000000e-01   1.10000000e-04   0.00000000e+00"/>
            <geometry>
                <mesh filename="package://roboy_simulation/arm/dae/collision_p-handflaeche-teil-2-v01.dae"
                      scale="1.0 1.0 1.0"/>
            </geometry>
        </collision>
        <visual name="arm__visual">
            <origin rpy="0    0   -1.57" xyz="1.50000000e-01   1.10000000e-04   0.00000000e+00"/>
            <geometry>
                <mesh filename="package://roboy_simulation/roboy/dae/p-handflaeche-teil-2-v01.dae OR roboy_simulation/arm/dae/p-handflaeche-teil-2-v01.dae"
                      scale="1 1 1"/>
            </geometry>
        </visual>
    </link>
    <link name="arm__upper_arm">
        <inertial>
            <mass value="1"/>
            <origin rpy="0  0  0" xyz="0    0.02 -0.5"/>
            <inertia ixx="1" ixy="0" ixz="0" iyy="1" iyz="0" izz="1"/>
        </inertial>
        <collision name="arm__collision">
            <origin rpy="0  0  0" xyz="0    0.02 -0.5"/>
            <geometry>
                <mesh filename="package://roboy_simulation/arm/dae/collision_p-oberarm-1-v02.dae" scale="1.0 1.0 1.0"/>
            </geometry>
        </collision>
        <visual name="arm__visual">
            <origin rpy="0  0  0" xyz="0    0.02 -0.5"/>
            <geometry>
                <mesh filename="package://roboy_simulation/roboy/dae/p-oberarm-1-v02.dae OR roboy_simulation/arm/dae/p-oberarm-1-v02.dae"
                      scale="1 1 1"/>
            </geometry>
        </visual>
    </link>
</robot>
