<robot name="legs_with_muscles_simplified">
    <link name="hip">
        <inertial>
            <origin
                    xyz="-0.0158870613870188 0.863216046052608 -0.0172960582809661"
                    rpy="0 0 0"/>
            <mass
                    value="1.51172861345358"/>
            <inertia
                    ixx="0.00636162418834724"
                    ixy="0.000429410633369766"
                    ixz="-4.28237566310602E-05"
                    iyy="0.0239035313706091"
                    iyz="0.000170071261779035"
                    izz="0.0224032802281935"/>
        </inertial>
        <visual>
            <origin
                    xyz="0 0 0"
                    rpy="0 0 0"/>
            <geometry>
                <mesh filename="package://roboy_simulation/legs_with_muscles_simplified/cad/hip.STL"/>
            </geometry>
            <material name="">
                <color rgba="0.792156862745098 0.819607843137255 0.933333333333333 1"/>
            </material>
        </visual>
        <collision>
            <origin xyz="0 0 0"
                    rpy="0 0 0"/>
            <geometry>
                <mesh
                        filename="package://roboy_simulation/legs_with_muscles_simplified/cad/hip.STL"/>
            </geometry>
        </collision>
    </link>
    <link name="thigh_left">
        <inertial>
            <origin
                    xyz="0.129946675222552 -0.276202710157228 -0.00235076375572906"
                    rpy="0 0 0"/>
            <mass
                    value="1.14282505604497"/>
            <inertia
                    ixx="0.0263386865218275"
                    ixy="-0.000545811177715892"
                    ixz="-3.23181853593676E-05"
                    iyy="0.00130562366879721"
                    iyz="0.000230008392994089"
                    izz="0.026154257925911"/>
        </inertial>
        <visual>
            <origin
                    xyz="0 0 0"
                    rpy="0 0 0"/>
            <geometry>
                <mesh
                        filename="package://roboy_simulation/legs_with_muscles_simplified/cad/thigh_left.STL"/>
            </geometry>
            <material
                    name="">
                <color
                        rgba="0.698039215686274 0.698039215686274 0.698039215686274 1"/>
            </material>
        </visual>
        <collision>
            <origin
                    xyz="0 0 0"
                    rpy="0 0 0"/>
            <geometry>
                <mesh
                        filename="package://roboy_simulation/legs_with_muscles_simplified/cad/thigh_left.STL"/>
            </geometry>
        </collision>
    </link>
    <joint
            name="groin_left"
            type="continuous">
        <origin
                xyz="-0.062496 0 0.815"
                rpy="1.5661 0.02622 3.1415"/>
        <parent
                link="hip"/>
        <child
                link="thigh_left"/>
        <axis
                xyz="0.99966 0.026217 0"/>
    </joint>
    <link
            name="shank_left">
        <inertial>
            <origin
                    xyz="0.00921348349929729 -0.119360783722429 -2.47501737064837E-06"
                    rpy="0 0 0"/>
            <mass
                    value="0.704951485952527"/>
            <inertia
                    ixx="0.00612600421748572"
                    ixy="4.75501737875398E-05"
                    ixz="4.11337827777844E-06"
                    iyy="0.000600644099427423"
                    iyz="2.67664316498766E-07"
                    izz="0.00570961452039471"/>
        </inertial>
        <visual>
            <origin
                    xyz="0 0 0"
                    rpy="0 0 0"/>
            <geometry>
                <mesh
                        filename="package://roboy_simulation/legs_with_muscles_simplified/cad/shank_left.STL"/>
            </geometry>
            <material
                    name="">
                <color
                        rgba="0.647058823529412 0.619607843137255 0.588235294117647 1"/>
            </material>
        </visual>
        <collision>
            <origin
                    xyz="0 0 0"
                    rpy="0 0 0"/>
            <geometry>
                <mesh
                        filename="package://roboy_simulation/legs_with_muscles_simplified/cad/shank_left.STL"/>
            </geometry>
        </collision>
    </link>
    <joint
            name="knee_left"
            type="fixed">
        <origin
                xyz="0.144763069678859 -0.424023361877471 -0.00526291087063863"
                rpy="3.0162475235073 -3.35835959736075E-14 -3.14159265358979"/>
        <parent
                link="thigh_left"/>
        <child
                link="shank_left"/>
        <axis
                xyz="0 0 0"/>
    </joint>
    <link
            name="foot_left">
        <inertial>
            <origin
                    xyz="0.0107877860873975 -0.0297125496016415 -0.0364994757209196"
                    rpy="0 0 0"/>
            <mass
                    value="0.286521012582186"/>
            <inertia
                    ixx="0.00123645260630993"
                    ixy="-8.16068398317443E-06"
                    ixz="-4.01100177272782E-05"
                    iyy="0.0011013641727408"
                    iyz="0.000184643052434811"
                    izz="0.000354223376391874"/>
        </inertial>
        <visual>
            <origin
                    xyz="0 0 0"
                    rpy="0 0 0"/>
            <geometry>
                <mesh
                        filename="package://roboy_simulation/legs_with_muscles_simplified/cad/foot_left.STL"/>
            </geometry>
            <material
                    name="">
                <color
                        rgba="0.698039215686274 0.698039215686274 0.698039215686274 1"/>
            </material>
        </visual>
        <collision>
            <origin
                    xyz="0 0 0"
                    rpy="0 0 0"/>
            <geometry>
                <mesh
                        filename="package://roboy_simulation/legs_with_muscles_simplified/cad/foot_left.STL"/>
            </geometry>
        </collision>
    </link>
    <joint
            name="ankle_left"
            type="fixed">
        <origin
                xyz="0 -0.355040992244245 0.00361652605413842"
                rpy="-0.0770234987828893 3.88415428292932E-17 2.95805081004883E-15"/>
        <parent
                link="shank_left"/>
        <child
                link="foot_left"/>
        <axis
                xyz="0 0 0"/>
    </joint>
    <link
            name="thigh_right">
        <inertial>
            <origin
                    xyz="0.12300475181818 -0.279551516307881 -0.000350187410034564"
                    rpy="0 0 0"/>
            <mass
                    value="1.14283855476689"/>
            <inertia
                    ixx="0.0263386885448544"
                    ixy="-0.000545804425920097"
                    ixz="-3.23133197262457E-05"
                    iyy="0.00130564712067707"
                    iyz="0.00022999470180684"
                    izz="0.0261542377185969"/>
        </inertial>
        <visual>
            <origin
                    xyz="0 0 0"
                    rpy="0 0 0"/>
            <geometry>
                <mesh
                        filename="package://roboy_simulation/legs_with_muscles_simplified/cad/thigh_right.STL"/>
            </geometry>
            <material
                    name="">
                <color
                        rgba="0.698039215686274 0.698039215686274 0.698039215686274 1"/>
            </material>
        </visual>
        <collision>
            <origin
                    xyz="0 0 0"
                    rpy="0 0 0"/>
            <geometry>
                <mesh
                        filename="package://roboy_simulation/legs_with_muscles_simplified/cad/thigh_right.STL"/>
            </geometry>
        </collision>
    </link>
    <joint
            name="groin_right"
            type="continuous">
        <origin
                xyz="0.069485 0 0.815"
                rpy="1.6236 0.0016831 8.9025E-05"/>
        <parent
                link="hip"/>
        <child
                link="thigh_right"/>
        <axis
                xyz="-1 -0.0016854 0"/>
    </joint>
    <link
            name="shank_right">
        <inertial>
            <origin
                    xyz="0.00921373744853038 -0.119360822850696 -2.50548577516302E-06"
                    rpy="0 0 0"/>
            <mass
                    value="0.704952036738416"/>
            <inertia
                    ixx="0.00612600759622845"
                    ixy="4.75499038464848E-05"
                    ixz="4.11419390261452E-06"
                    iyy="0.000600645216686691"
                    iyz="2.7459805041223E-07"
                    izz="0.0057096173474834"/>
        </inertial>
        <visual>
            <origin
                    xyz="0 0 0"
                    rpy="0 0 0"/>
            <geometry>
                <mesh
                        filename="package://roboy_simulation/legs_with_muscles_simplified/cad/shank_right.STL"/>
            </geometry>
            <material
                    name="">
                <color
                        rgba="0.647058823529412 0.619607843137255 0.588235294117647 1"/>
            </material>
        </visual>
        <collision>
            <origin
                    xyz="0 0 0"
                    rpy="0 0 0"/>
            <geometry>
                <mesh
                        filename="package://roboy_simulation/legs_with_muscles_simplified/cad/shank_right.STL"/>
            </geometry>
        </collision>
    </link>
    <joint
            name="knee_right"
            type="fixed">
        <origin
                xyz="0.120208874962923 -0.427371564309398 -0.00326291087061965"
                rpy="-0.161848636669967 2.68919950327171E-14 -1.94635719894714E-15"/>
        <parent
                link="thigh_right"/>
        <child
                link="shank_right"/>
        <axis
                xyz="0 0 0"/>
    </joint>
    <link
            name="foot_right">
        <inertial>
            <origin
                    xyz="0.00732723854730483 -0.0118633634806553 -0.0417700813303313"
                    rpy="0 0 0"/>
            <mass
                    value="0.137648576749439"/>
            <inertia
                    ixx="0.000751451325340605"
                    ixy="7.22382790720835E-06"
                    ixz="3.24934876594634E-05"
                    iyy="0.00064206599367226"
                    iyz="0.000214926548330912"
                    izz="0.000176648048224259"/>
        </inertial>
        <visual>
            <origin
                    xyz="0 0 0"
                    rpy="0 0 0"/>
            <geometry>
                <mesh
                        filename="package://roboy_simulation/legs_with_muscles_simplified/cad/foot_right.STL"/>
            </geometry>
            <material
                    name="">
                <color
                        rgba="0.698039215686274 0.698039215686274 0.698039215686274 1"/>
            </material>
        </visual>
        <collision>
            <origin
                    xyz="0 0 0"
                    rpy="0 0 0"/>
            <geometry>
                <mesh
                        filename="package://roboy_simulation/legs_with_muscles_simplified/cad/foot_right.STL"/>
            </geometry>
        </collision>
    </link>
    <joint
            name="ankle_right"
            type="fixed">
        <origin
                xyz="0 -0.354510369428197 0.00790748776522339"
                rpy="-0.169048430832731 -5.86005040065923E-14 -3.10876338235379E-16"/>
        <parent
                link="shank_right"/>
        <child
                link="foot_right"/>
        <axis
                xyz="0 0 0"/>
    </joint>
</robot>