<sdf version='1.5'>
  <world name='default'>
<model name='roboy'>

 <static>false</static>

    <link name='roboy_torso'>
            <gravity>1</gravity>
      <pose frame=''>-0 0 0.75 1.5707 0 1.5707</pose>
      <inertial>
        <mass>1</mass>
        <pose frame=''>0 0 0 0 -0 0</pose>
        <inertia>
          <ixx>1</ixx>
          <ixy>0</ixy>
          <ixz>0</ixz>
          <iyy>1</iyy>
          <iyz>0</iyz>
          <izz>1</izz>
        </inertia>
      </inertial>
      <self_collide>0</self_collide>
      <kinematic>0</kinematic>
      <visual name='visual'>
        <geometry>
          <mesh>
            <scale>1 1 1</scale>
            <uri>model://roboy/dae/baugruppe_oberkoerper_fuer_mep.dae</uri>
          </mesh>
        </geometry>
        <pose frame=''>0 0 0 0 -0 0</pose>
        <cast_shadows>1</cast_shadows>
        <transparency>0</transparency>
      </visual>
      <collision name='collision'>
        <laser_retro>0</laser_retro>
        <max_contacts>10</max_contacts>
        <pose frame=''>0 0 0 0 -0 0</pose>
        <geometry>
          <mesh>
            <uri>model://roboy/dae/baugruppe_oberkoerper_fuer_mep.dae</uri>
          </mesh>
        </geometry>
        <surface>
          <friction>
            <ode>
              <mu>1</mu>
              <mu2>1</mu2>
              <fdir1>0 0 0</fdir1>
              <slip1>0</slip1>
              <slip2>0</slip2>
            </ode>
          </friction>
          <bounce>
            <restitution_coefficient>0</restitution_coefficient>
            <threshold>1e+06</threshold>
          </bounce>
          <contact>
            <collide_without_contact>0</collide_without_contact>
            <collide_without_contact_bitmask>1</collide_without_contact_bitmask>
            <collide_bitmask>1</collide_bitmask>
            <ode>
              <soft_cfm>0</soft_cfm>
              <soft_erp>0.2</soft_erp>
              <kp>1e+13</kp>
              <kd>1</kd>
              <max_vel>0.01</max_vel>
              <min_depth>0</min_depth>
            </ode>
            <bullet>
              <split_impulse>1</split_impulse>
              <split_impulse_penetration_threshold>-0.01</split_impulse_penetration_threshold>
              <soft_cfm>0</soft_cfm>
              <soft_erp>0.2</soft_erp>
              <kp>1e+13</kp>
              <kd>1</kd>
            </bullet>
          </contact>
        </surface>
      </collision>
    </link>
   

    <link name='box'>
      <pose frame=''>-0.08 0 0.275 0 -0 0</pose>
      <gravity>1</gravity>
      <self_collide>0</self_collide>
      <kinematic>0</kinematic>
      <inertial>
        <mass>1</mass>
        <pose frame=''>-0 0 0 0 -0 0</pose>
        <inertia>
          <ixx>1</ixx>
          <ixy>0</ixy>
          <ixz>0</ixz>
          <iyy>1</iyy>
          <iyz>0</iyz>
          <izz>1</izz>
        </inertia>
      </inertial>
      <visual name='visual'>
        <pose frame=''>0 0 0 0 -0 0</pose>
        <geometry>
          <box>
            <size>0.57 0.57 0.57</size>
          </box>
        </geometry>
        <cast_shadows>1</cast_shadows>
        <transparency>0</transparency>
      </visual>
      <collision name='collision'>
        <laser_retro>0</laser_retro>
        <max_contacts>10</max_contacts>
        <pose frame=''>0 0 0 0 -0 0</pose>
        <geometry>
          <box>
            <size>0.57 0.57 0.57</size>
          </box>
        </geometry>
        <surface>
          <friction>
            <ode>
              <mu>1</mu>
              <mu2>1</mu2>
              <fdir1>0 0 0</fdir1>
              <slip1>0</slip1>
              <slip2>0</slip2>
            </ode>
          </friction>
          <bounce>
            <restitution_coefficient>0</restitution_coefficient>
            <threshold>1e+06</threshold>
          </bounce>
          <contact>
            <collide_without_contact>0</collide_without_contact>
            <collide_without_contact_bitmask>1</collide_without_contact_bitmask>
            <collide_bitmask>1</collide_bitmask>
            <ode>
              <soft_cfm>0</soft_cfm>
              <soft_erp>0.2</soft_erp>
              <kp>1e+13</kp>
              <kd>1</kd>
              <max_vel>0.01</max_vel>
              <min_depth>0</min_depth>
            </ode>
            <bullet>
              <split_impulse>1</split_impulse>
              <split_impulse_penetration_threshold>-0.01</split_impulse_penetration_threshold>
              <soft_cfm>0</soft_cfm>
              <soft_erp>0.2</soft_erp>
              <kp>1e+13</kp>
              <kd>1</kd>
            </bullet>
          </contact>
        </surface>
      </collision>
    </link>


    <link name='roboy_head'>
      <pose frame=''>-0 0 1.095 1.57 -0 1.57</pose>
      <gravity>1</gravity>
      <inertial>
        <mass>1</mass>
        <pose frame=''>0 0 0 0 -0 0</pose>
        <inertia>
          <ixx>1</ixx>
          <ixy>0</ixy>
          <ixz>0</ixz>
          <iyy>1</iyy>
          <iyz>0</iyz>
          <izz>1</izz>
        </inertia>
      </inertial>
      <self_collide>0</self_collide>
      <kinematic>0</kinematic>
      <visual name='visual'>
        <geometry>
          <mesh>
            <scale>1 1 1</scale>
            <uri>model://roboy/dae/121213_PROTOTYP_Kopf-Vorderteil.dae</uri>
          </mesh>
        </geometry>
        <pose frame=''>0 0 0 0 -0 0</pose>
        <cast_shadows>1</cast_shadows>
        <transparency>0</transparency>
      </visual>
      <collision name='collision'>
        <laser_retro>0</laser_retro>
        <max_contacts>10</max_contacts>
        <pose frame=''>0 0 0 0 -0 0</pose>
        <geometry>
          <mesh>
            <uri>model://roboy/dae/121213_PROTOTYP_Kopf-Vorderteil.dae</uri>
          </mesh>
        </geometry>
        <surface>
          <friction>
            <ode>
              <mu>1</mu>
              <mu2>1</mu2>
              <fdir1>0 0 0</fdir1>
              <slip1>0</slip1>
              <slip2>0</slip2>
            </ode>
          </friction>
          <bounce>
            <restitution_coefficient>0</restitution_coefficient>
            <threshold>1e+06</threshold>
          </bounce>
          <contact>
            <collide_without_contact>0</collide_without_contact>
            <collide_without_contact_bitmask>1</collide_without_contact_bitmask>
            <collide_bitmask>1</collide_bitmask>
            <ode>
              <soft_cfm>0</soft_cfm>
              <soft_erp>0.2</soft_erp>
              <kp>1e+13</kp>
              <kd>1</kd>
              <max_vel>0.01</max_vel>
              <min_depth>0</min_depth>
            </ode>
            <bullet>
              <split_impulse>1</split_impulse>
              <split_impulse_penetration_threshold>-0.01</split_impulse_penetration_threshold>
              <soft_cfm>0</soft_cfm>
              <soft_erp>0.2</soft_erp>
              <kp>1e+13</kp>
              <kd>1</kd>
            </bullet>
          </contact>
        </surface>
      </collision>
    </link>
    <link name='roboy_left_foot'>
      <pose frame=''>0.3 0.088 0.33 1.57 0 -1.57</pose>
      <gravity>1</gravity>
      <inertial>
        <mass>1</mass>
        <pose frame=''>0 0 0 0 -0 0</pose>
        <inertia>
          <ixx>1</ixx>
          <ixy>0</ixy>
          <ixz>0</ixz>
          <iyy>1</iyy>
          <iyz>0</iyz>
          <izz>1</izz>
        </inertia>
      </inertial>
      <self_collide>0</self_collide>
      <kinematic>0</kinematic>
      <gravity>1</gravity>
      <visual name='visual'>
        <geometry>
          <mesh>
            <scale>1 1 1</scale>
            <uri>model://roboy/dae/p-fuss-links-v12.dae</uri>
          </mesh>
        </geometry>
        <pose frame=''>0 0 0 0 -0 0</pose>
        <cast_shadows>1</cast_shadows>
        <transparency>0</transparency>
      </visual>
      <collision name='collision'>
        <laser_retro>0</laser_retro>
        <max_contacts>10</max_contacts>
        <pose frame=''>0 0 0 0 -0 0</pose>
        <geometry>
          <mesh>
            <uri>model://roboy/dae/p-fuss-links-v12.dae</uri>
          </mesh>
        </geometry>
        <surface>
          <friction>
            <ode>
              <mu>1</mu>
              <mu2>1</mu2>
              <fdir1>0 0 0</fdir1>
              <slip1>0</slip1>
              <slip2>0</slip2>
            </ode>
          </friction>
          <bounce>
            <restitution_coefficient>0</restitution_coefficient>
            <threshold>1e+06</threshold>
          </bounce>
          <contact>
            <collide_without_contact>0</collide_without_contact>
            <collide_without_contact_bitmask>1</collide_without_contact_bitmask>
            <collide_bitmask>1</collide_bitmask>
            <ode>
              <soft_cfm>0</soft_cfm>
              <soft_erp>0.2</soft_erp>
              <kp>1e+13</kp>
              <kd>1</kd>
              <max_vel>0.01</max_vel>
              <min_depth>0</min_depth>
            </ode>
            <bullet>
              <split_impulse>1</split_impulse>
              <split_impulse_penetration_threshold>-0.01</split_impulse_penetration_threshold>
              <soft_cfm>0</soft_cfm>
              <soft_erp>0.2</soft_erp>
              <kp>1e+13</kp>
              <kd>1</kd>
            </bullet>
          </contact>
        </surface>
      </collision>
    </link>
    <link name='roboy_left_hand'>
      <pose frame=''>0.14 0.22 0.85 0 0 -1.5707</pose>
      <gravity>1</gravity>
      <inertial>
        <mass>1</mass>
        <pose frame=''>0 0 0 0 -0 0</pose>
        <inertia>
          <ixx>1</ixx>
          <ixy>0</ixy>
          <ixz>0</ixz>
          <iyy>1</iyy>
          <iyz>0</iyz>
          <izz>1</izz>
        </inertia>
      </inertial>
      <self_collide>0</self_collide>
      <kinematic>0</kinematic>
      <visual name='visual'>
        <geometry>
          <mesh>
            <scale>1 1 1</scale>
            <uri>model://roboy/dae/p-handflaeche-teil-2-v01.dae</uri>
          </mesh>
        </geometry>
        <pose frame=''>0 0 0 0 -0 0</pose>
        <cast_shadows>1</cast_shadows>
        <transparency>0</transparency>
      </visual>
      <collision name='collision'>
        <laser_retro>0</laser_retro>
        <max_contacts>10</max_contacts>
        <pose frame=''>0 0 0 0 -0 0</pose>
        <geometry>
          <mesh>
            <uri>model://roboy/dae/p-handflaeche-teil-2-v01.dae</uri>
          </mesh>
        </geometry>
        <surface>
          <friction>
            <ode>
              <mu>1</mu>
              <mu2>1</mu2>
              <fdir1>0 0 0</fdir1>
              <slip1>0</slip1>
              <slip2>0</slip2>
            </ode>
          </friction>
          <bounce>
            <restitution_coefficient>0</restitution_coefficient>
            <threshold>1e+06</threshold>
          </bounce>
          <contact>
            <collide_without_contact>0</collide_without_contact>
            <collide_without_contact_bitmask>1</collide_without_contact_bitmask>
            <collide_bitmask>1</collide_bitmask>
            <ode>
              <soft_cfm>0</soft_cfm>
              <soft_erp>0.2</soft_erp>
              <kp>1e+13</kp>
              <kd>1</kd>
              <max_vel>0.01</max_vel>
              <min_depth>0</min_depth>
            </ode>
            <bullet>
              <split_impulse>1</split_impulse>
              <split_impulse_penetration_threshold>-0.01</split_impulse_penetration_threshold>
              <soft_cfm>0</soft_cfm>
              <soft_erp>0.2</soft_erp>
              <kp>1e+13</kp>
              <kd>1</kd>
            </bullet>
          </contact>
        </surface>
      </collision>
    </link>
    <link name='roboy_left_shin'>
      <pose frame=''>0.3 0.075 0.84 1.57 0 -1.57</pose>
      <gravity>1</gravity>
      <inertial>
        <mass>1</mass>
        <pose frame=''>0 0 0 0 -0 0</pose>
        <inertia>
          <ixx>1</ixx>
          <ixy>0</ixy>
          <ixz>0</ixz>
          <iyy>1</iyy>
          <iyz>0</iyz>
          <izz>1</izz>
        </inertia>
      </inertial>
      <self_collide>0</self_collide>
      <kinematic>0</kinematic>
      <visual name='visual'>
        <geometry>
          <mesh>
            <scale>1 1 1</scale>
            <uri>model://roboy/dae/p-unterschenkel-v02.dae</uri>
          </mesh>
        </geometry>
        <pose frame=''>0 0 0 0 -0 0</pose>
        <cast_shadows>1</cast_shadows>
        <transparency>0</transparency>
      </visual>
      <collision name='collision'>
        <laser_retro>0</laser_retro>
        <max_contacts>10</max_contacts>
        <pose frame=''>0 0 0 0 -0 0</pose>
        <geometry>
          <mesh>
            <uri>model://roboy/dae/p-unterschenkel-v02.dae</uri>
          </mesh>
        </geometry>
        <surface>
          <friction>
            <ode>
              <mu>1</mu>
              <mu2>1</mu2>
              <fdir1>0 0 0</fdir1>
              <slip1>0</slip1>
              <slip2>0</slip2>
            </ode>
          </friction>
          <bounce>
            <restitution_coefficient>0</restitution_coefficient>
            <threshold>1e+06</threshold>
          </bounce>
          <contact>
            <collide_without_contact>0</collide_without_contact>
            <collide_without_contact_bitmask>1</collide_without_contact_bitmask>
            <collide_bitmask>1</collide_bitmask>
            <ode>
              <soft_cfm>0</soft_cfm>
              <soft_erp>0.2</soft_erp>
              <kp>1e+13</kp>
              <kd>1</kd>
              <max_vel>0.01</max_vel>
              <min_depth>0</min_depth>
            </ode>
            <bullet>
              <split_impulse>1</split_impulse>
              <split_impulse_penetration_threshold>-0.01</split_impulse_penetration_threshold>
              <soft_cfm>0</soft_cfm>
              <soft_erp>0.2</soft_erp>
              <kp>1e+13</kp>
              <kd>1</kd>
            </bullet>
          </contact>
        </surface>
      </collision>
    </link>
    <link name='roboy_left_thigh'>
      <pose frame=''>-0 0.075 0.6 3.14 -0 -1.57</pose>
      <gravity>1</gravity>
      <inertial>
        <mass>1</mass>
        <pose frame=''>0 0 0 0 -0 0</pose>
        <inertia>
          <ixx>1</ixx>
          <ixy>0</ixy>
          <ixz>0</ixz>
          <iyy>1</iyy>
          <iyz>0</iyz>
          <izz>1</izz>
        </inertia>
      </inertial>
      <self_collide>0</self_collide>
      <kinematic>0</kinematic>
      <visual name='visual'>
        <geometry>
          <mesh>
            <scale>1 1 1</scale>
            <uri>model://roboy/dae/p-oberschenkel-v02.dae</uri>
          </mesh>
        </geometry>
        <pose frame=''>0 0 0 0 -0 0</pose>
        <cast_shadows>1</cast_shadows>
        <transparency>0</transparency>
      </visual>
      <collision name='collision'>
        <laser_retro>0</laser_retro>
        <max_contacts>10</max_contacts>
        <pose frame=''>0 0 0 0 -0 0</pose>
        <geometry>
          <mesh>
            <uri>model://roboy/dae/p-oberschenkel-v02.dae</uri>
          </mesh>
        </geometry>
        <surface>
          <friction>
            <ode>
              <mu>1</mu>
              <mu2>1</mu2>
              <fdir1>0 0 0</fdir1>
              <slip1>0</slip1>
              <slip2>0</slip2>
            </ode>
          </friction>
          <bounce>
            <restitution_coefficient>0</restitution_coefficient>
            <threshold>1e+06</threshold>
          </bounce>
          <contact>
            <collide_without_contact>0</collide_without_contact>
            <collide_without_contact_bitmask>1</collide_without_contact_bitmask>
            <collide_bitmask>1</collide_bitmask>
            <ode>
              <soft_cfm>0</soft_cfm>
              <soft_erp>0.2</soft_erp>
              <kp>1e+13</kp>
              <kd>1</kd>
              <max_vel>0.01</max_vel>
              <min_depth>0</min_depth>
            </ode>
            <bullet>
              <split_impulse>1</split_impulse>
              <split_impulse_penetration_threshold>-0.01</split_impulse_penetration_threshold>
              <soft_cfm>0</soft_cfm>
              <soft_erp>0.2</soft_erp>
              <kp>1e+13</kp>
              <kd>1</kd>
            </bullet>
          </contact>
        </surface>
      </collision>
    </link>
    <link name='roboy_left_upper_arm'>
      <pose frame=''>-0 0.22 1.07 1.57 -0 1.5707</pose>
      <gravity>1</gravity>
      <inertial>
        <mass>1</mass>
        <pose frame=''>0 0 0 0 -0 0</pose>
        <inertia>
          <ixx>1</ixx>
          <ixy>0</ixy>
          <ixz>0</ixz>
          <iyy>1</iyy>
          <iyz>0</iyz>
          <izz>1</izz>
        </inertia>
      </inertial>
      <self_collide>0</self_collide>
      <kinematic>0</kinematic>
      <visual name='visual'>
        <geometry>
          <mesh>
            <scale>1 1 1</scale>
            <uri>model://roboy/dae/p-oberarm-1-v02.dae</uri>
          </mesh>
        </geometry>
        <pose frame=''>0 0 0 0 -0 0</pose>
        <cast_shadows>1</cast_shadows>
        <transparency>0</transparency>
      </visual>
      <collision name='collision_0'>
        <laser_retro>0</laser_retro>
        <max_contacts>10</max_contacts>
        <pose frame=''>0 0 0 0 -0 0</pose>
        <geometry>
          <mesh>
            <uri>model://roboy/dae/p-oberarm-1-v02.dae</uri>
          </mesh>
        </geometry>
        <surface>
          <friction>
            <ode>
              <mu>1</mu>
              <mu2>1</mu2>
              <fdir1>0 0 0</fdir1>
              <slip1>0</slip1>
              <slip2>0</slip2>
            </ode>
          </friction>
          <bounce>
            <restitution_coefficient>0</restitution_coefficient>
            <threshold>1e+06</threshold>
          </bounce>
          <contact>
            <collide_without_contact>0</collide_without_contact>
            <collide_without_contact_bitmask>1</collide_without_contact_bitmask>
            <collide_bitmask>1</collide_bitmask>
            <ode>
              <soft_cfm>0</soft_cfm>
              <soft_erp>0.2</soft_erp>
              <kp>1e+13</kp>
              <kd>1</kd>
              <max_vel>0.01</max_vel>
              <min_depth>0</min_depth>
            </ode>
            <bullet>
              <split_impulse>1</split_impulse>
              <split_impulse_penetration_threshold>-0.01</split_impulse_penetration_threshold>
              <soft_cfm>0</soft_cfm>
              <soft_erp>0.2</soft_erp>
              <kp>1e+13</kp>
              <kd>1</kd>
            </bullet>
          </contact>
        </surface>
      </collision>
    </link>
    <link name='roboy_pelvis'>
      <pose frame=''>-0 0 0.66 1.57 -0 1.57</pose>
      <gravity>1</gravity>
      <inertial>
        <mass>1</mass>
        <pose frame=''>0 0 0 0 -0 0</pose>
        <inertia>
          <ixx>1</ixx>
          <ixy>0</ixy>
          <ixz>0</ixz>
          <iyy>1</iyy>
          <iyz>0</iyz>
          <izz>1</izz>
        </inertia>
      </inertial>
      <self_collide>0</self_collide>
      <kinematic>0</kinematic>
      <visual name='visual'>
        <geometry>
          <mesh>
            <scale>1 1 1</scale>
            <uri>model://roboy/dae/p-becken-v06.dae</uri>
          </mesh>
        </geometry>
        <pose frame=''>0 0 0 0 -0 0</pose>
        <cast_shadows>1</cast_shadows>
        <transparency>0</transparency>
      </visual>
      <collision name='collision'>
        <laser_retro>0</laser_retro>
        <max_contacts>10</max_contacts>
        <pose frame=''>0 0 0 0 -0 0</pose>
        <geometry>
          <mesh>
            <uri>model://roboy/dae/p-becken-v06.dae</uri>
          </mesh>
        </geometry>
        <surface>
          <friction>
            <ode>
              <mu>1</mu>
              <mu2>1</mu2>
              <fdir1>0 0 0</fdir1>
              <slip1>0</slip1>
              <slip2>0</slip2>
            </ode>
          </friction>
          <bounce>
            <restitution_coefficient>0</restitution_coefficient>
            <threshold>1e+06</threshold>
          </bounce>
          <contact>
            <collide_without_contact>0</collide_without_contact>
            <collide_without_contact_bitmask>1</collide_without_contact_bitmask>
            <collide_bitmask>1</collide_bitmask>
            <ode>
              <soft_cfm>0</soft_cfm>
              <soft_erp>0.2</soft_erp>
              <kp>1e+13</kp>
              <kd>1</kd>
              <max_vel>0.01</max_vel>
              <min_depth>0</min_depth>
            </ode>
            <bullet>
              <split_impulse>1</split_impulse>
              <split_impulse_penetration_threshold>-0.01</split_impulse_penetration_threshold>
              <soft_cfm>0</soft_cfm>
              <soft_erp>0.2</soft_erp>
              <kp>1e+13</kp>
              <kd>1</kd>
            </bullet>
          </contact>
        </surface>
      </collision>
    </link>
    <link name='roboy_right_foot'>
      <pose frame=''>0.3 -0.068 0.33 1.57 0 -1.57</pose>
      <gravity>1</gravity>
      <inertial>
        <mass>1</mass>
        <pose frame=''>0 0 0 0 -0 0</pose>
        <inertia>
          <ixx>1</ixx>
          <ixy>0</ixy>
          <ixz>0</ixz>
          <iyy>1</iyy>
          <iyz>0</iyz>
          <izz>1</izz>
        </inertia>
      </inertial>
      <self_collide>0</self_collide>
      <kinematic>0</kinematic>
      <gravity>1</gravity>
      <visual name='visual'>
        <geometry>
          <mesh>
            <scale>1 1 1</scale>
            <uri>model://roboy/dae/p-fuss-links-v12.dae</uri>
          </mesh>
        </geometry>
        <pose frame=''>0 0 0 0 -0 0</pose>
        <cast_shadows>1</cast_shadows>
        <transparency>0</transparency>
      </visual>
      <collision name='collision'>
        <laser_retro>0</laser_retro>
        <max_contacts>10</max_contacts>
        <pose frame=''>0 0 0 0 -0 0</pose>
        <geometry>
          <mesh>
            <uri>model://roboy/dae/p-fuss-links-v12.dae</uri>
          </mesh>
        </geometry>
        <surface>
          <friction>
            <ode>
              <mu>1</mu>
              <mu2>1</mu2>
              <fdir1>0 0 0</fdir1>
              <slip1>0</slip1>
              <slip2>0</slip2>
            </ode>
          </friction>
          <bounce>
            <restitution_coefficient>0</restitution_coefficient>
            <threshold>1e+06</threshold>
          </bounce>
          <contact>
            <collide_without_contact>0</collide_without_contact>
            <collide_without_contact_bitmask>1</collide_without_contact_bitmask>
            <collide_bitmask>1</collide_bitmask>
            <ode>
              <soft_cfm>0</soft_cfm>
              <soft_erp>0.2</soft_erp>
              <kp>1e+13</kp>
              <kd>1</kd>
              <max_vel>0.01</max_vel>
              <min_depth>0</min_depth>
            </ode>
            <bullet>
              <split_impulse>1</split_impulse>
              <split_impulse_penetration_threshold>-0.01</split_impulse_penetration_threshold>
              <soft_cfm>0</soft_cfm>
              <soft_erp>0.2</soft_erp>
              <kp>1e+13</kp>
              <kd>1</kd>
            </bullet>
          </contact>
        </surface>
      </collision>
    </link>
    <link name='roboy_right_hand'>
      <pose frame=''>0.14 -0.22 0.85 -3.14 -0 1.57</pose>
      <gravity>1</gravity>
      <inertial>
        <mass>1</mass>
        <pose frame=''>0 0 0 0 -0 0</pose>
        <inertia>
          <ixx>1</ixx>
          <ixy>0</ixy>
          <ixz>0</ixz>
          <iyy>1</iyy>
          <iyz>0</iyz>
          <izz>1</izz>
        </inertia>
      </inertial>
      <self_collide>0</self_collide>
      <kinematic>0</kinematic>
      <visual name='visual'>
        <geometry>
          <mesh>
            <scale>1 1 1</scale>
            <uri>model://roboy/dae/p-handflaeche-teil-2-v01.dae</uri>
          </mesh>
        </geometry>
        <pose frame=''>0 0 0 0 -0 0</pose>
        <cast_shadows>1</cast_shadows>
        <transparency>0</transparency>
      </visual>
      <collision name='collision'>
        <laser_retro>0</laser_retro>
        <max_contacts>10</max_contacts>
        <pose frame=''>0 0 0 0 -0 0</pose>
        <geometry>
          <mesh>
            <uri>model://roboy/dae/p-handflaeche-teil-2-v01.dae</uri>
          </mesh>
        </geometry>
        <surface>
          <friction>
            <ode>
              <mu>1</mu>
              <mu2>1</mu2>
              <fdir1>0 0 0</fdir1>
              <slip1>0</slip1>
              <slip2>0</slip2>
            </ode>
          </friction>
          <bounce>
            <restitution_coefficient>0</restitution_coefficient>
            <threshold>1e+06</threshold>
          </bounce>
          <contact>
            <collide_without_contact>0</collide_without_contact>
            <collide_without_contact_bitmask>1</collide_without_contact_bitmask>
            <collide_bitmask>1</collide_bitmask>
            <ode>
              <soft_cfm>0</soft_cfm>
              <soft_erp>0.2</soft_erp>
              <kp>1e+13</kp>
              <kd>1</kd>
              <max_vel>0.01</max_vel>
              <min_depth>0</min_depth>
            </ode>
            <bullet>
              <split_impulse>1</split_impulse>
              <split_impulse_penetration_threshold>-0.01</split_impulse_penetration_threshold>
              <soft_cfm>0</soft_cfm>
              <soft_erp>0.2</soft_erp>
              <kp>1e+13</kp>
              <kd>1</kd>
            </bullet>
          </contact>
        </surface>
      </collision>
    </link>
    <link name='roboy_right_shin'>
      <pose frame=''>0.3 -0.075 0.84 1.57 -0 1.57</pose>
      <gravity>1</gravity>
      <inertial>
        <mass>1</mass>
        <pose frame=''>0 0 0 0 -0 0</pose>
        <inertia>
          <ixx>1</ixx>
          <ixy>0</ixy>
          <ixz>0</ixz>
          <iyy>1</iyy>
          <iyz>0</iyz>
          <izz>1</izz>
        </inertia>
      </inertial>
      <self_collide>0</self_collide>
      <kinematic>0</kinematic>
      <visual name='visual'>
        <geometry>
          <mesh>
            <scale>1 1 1</scale>
            <uri>model://roboy/dae/p-unterschenkel-v02.dae</uri>
          </mesh>
        </geometry>
        <pose frame=''>0 0 0 0 -0 0</pose>
        <cast_shadows>1</cast_shadows>
        <transparency>0</transparency>
      </visual>
      <collision name='collision'>
        <laser_retro>0</laser_retro>
        <max_contacts>10</max_contacts>
        <pose frame=''>0 0 0 0 -0 0</pose>
        <geometry>
          <mesh>
            <uri>model://roboy/dae/p-unterschenkel-v02.dae</uri>
          </mesh>
        </geometry>
        <surface>
          <friction>
            <ode>
              <mu>1</mu>
              <mu2>1</mu2>
              <fdir1>0 0 0</fdir1>
              <slip1>0</slip1>
              <slip2>0</slip2>
            </ode>
          </friction>
          <bounce>
            <restitution_coefficient>0</restitution_coefficient>
            <threshold>1e+06</threshold>
          </bounce>
          <contact>
            <collide_without_contact>0</collide_without_contact>
            <collide_without_contact_bitmask>1</collide_without_contact_bitmask>
            <collide_bitmask>1</collide_bitmask>
            <ode>
              <soft_cfm>0</soft_cfm>
              <soft_erp>0.2</soft_erp>
              <kp>1e+13</kp>
              <kd>1</kd>
              <max_vel>0.01</max_vel>
              <min_depth>0</min_depth>
            </ode>
            <bullet>
              <split_impulse>1</split_impulse>
              <split_impulse_penetration_threshold>-0.01</split_impulse_penetration_threshold>
              <soft_cfm>0</soft_cfm>
              <soft_erp>0.2</soft_erp>
              <kp>1e+13</kp>
              <kd>1</kd>
            </bullet>
          </contact>
        </surface>
      </collision>
    </link>
    <link name='roboy_right_thigh'>
      <pose frame=''>-0 -0.075 0.6 0 0 1.57009</pose>
      <gravity>1</gravity>
      <inertial>
        <mass>1</mass>
        <pose frame=''>0 0 0 0 -0 0</pose>
        <inertia>
          <ixx>1</ixx>
          <ixy>0</ixy>
          <ixz>0</ixz>
          <iyy>1</iyy>
          <iyz>0</iyz>
          <izz>1</izz>
        </inertia>
      </inertial>
      <self_collide>0</self_collide>
      <kinematic>0</kinematic>
      <visual name='visual'>
        <geometry>
          <mesh>
            <scale>1 1 1</scale>
            <uri>model://roboy/dae/p-oberschenkel-v02.dae</uri>
          </mesh>
        </geometry>
        <pose frame=''>0 0 0 0 -0 0</pose>
        <cast_shadows>1</cast_shadows>
        <transparency>0</transparency>
      </visual>
      <collision name='collision'>
        <laser_retro>0</laser_retro>
        <max_contacts>10</max_contacts>
        <pose frame=''>0 0 0 0 -0 0</pose>
        <geometry>
          <mesh>
            <uri>model://roboy/dae/p-oberschenkel-v02.dae</uri>
          </mesh>
        </geometry>
        <surface>
          <friction>
            <ode>
              <mu>1</mu>
              <mu2>1</mu2>
              <fdir1>0 0 0</fdir1>
              <slip1>0</slip1>
              <slip2>0</slip2>
            </ode>
          </friction>
          <bounce>
            <restitution_coefficient>0</restitution_coefficient>
            <threshold>1e+06</threshold>
          </bounce>
          <contact>
            <collide_without_contact>0</collide_without_contact>
            <collide_without_contact_bitmask>1</collide_without_contact_bitmask>
            <collide_bitmask>1</collide_bitmask>
            <ode>
              <soft_cfm>0</soft_cfm>
              <soft_erp>0.2</soft_erp>
              <kp>1e+13</kp>
              <kd>1</kd>
              <max_vel>0.01</max_vel>
              <min_depth>0</min_depth>
            </ode>
            <bullet>
              <split_impulse>1</split_impulse>
              <split_impulse_penetration_threshold>-0.01</split_impulse_penetration_threshold>
              <soft_cfm>0</soft_cfm>
              <soft_erp>0.2</soft_erp>
              <kp>1e+13</kp>
              <kd>1</kd>
            </bullet>
          </contact>
        </surface>
      </collision>
    </link>
    <link name='roboy_right_upper_arm'>
      <pose frame=''>-0 -0.22 1.07 1.5707 -0 -1.5707</pose>
      <gravity>1</gravity>
      <inertial>
        <mass>1</mass>
        <pose frame=''>0 0 0 0 -0 0</pose>
        <inertia>
          <ixx>1</ixx>
          <ixy>0</ixy>
          <ixz>0</ixz>
          <iyy>1</iyy>
          <iyz>0</iyz>
          <izz>1</izz>
        </inertia>
      </inertial>
      <self_collide>0</self_collide>
      <kinematic>0</kinematic>
      <visual name='visual'>
        <geometry>
          <mesh>
            <scale>1 1 1</scale>
            <uri>model://roboy/dae/p-oberarm-1-v02.dae</uri>
          </mesh>
        </geometry>
        <pose frame=''>0 0 0 0 -0 0</pose>
        <cast_shadows>1</cast_shadows>
        <transparency>0</transparency>
      </visual>
      <collision name='collision'>
        <laser_retro>0</laser_retro>
        <max_contacts>10</max_contacts>
        <pose frame=''>0 0 0 0 -0 0</pose>
        <geometry>
          <mesh>
            <uri>model://roboy/dae/p-oberarm-1-v02.dae</uri>
          </mesh>
        </geometry>
        <surface>
          <friction>
            <ode>
              <mu>1</mu>
              <mu2>1</mu2>
              <fdir1>0 0 0</fdir1>
              <slip1>0</slip1>
              <slip2>0</slip2>
            </ode>
          </friction>
          <bounce>
            <restitution_coefficient>0</restitution_coefficient>
            <threshold>1e+06</threshold>
          </bounce>
          <contact>
            <collide_without_contact>0</collide_without_contact>
            <collide_without_contact_bitmask>1</collide_without_contact_bitmask>
            <collide_bitmask>1</collide_bitmask>
            <ode>
              <soft_cfm>0</soft_cfm>
              <soft_erp>0.2</soft_erp>
              <kp>1e+13</kp>
              <kd>1</kd>
              <max_vel>0.01</max_vel>
              <min_depth>0</min_depth>
            </ode>
            <bullet>
              <split_impulse>1</split_impulse>
              <split_impulse_penetration_threshold>-0.01</split_impulse_penetration_threshold>
              <soft_cfm>0</soft_cfm>
              <soft_erp>0.2</soft_erp>
              <kp>1e+13</kp>
              <kd>1</kd>
            </bullet>
          </contact>
        </surface>
      </collision>
    </link>
    <static>1</static>
    <allow_auto_disable>1</allow_auto_disable>

    <joint name="right elbow" type="revolute">
      <pose> 0 -0.15 0 0 0 1.57</pose>
      <child>roboy_right_hand</child>
      <parent>roboy_right_upper_arm</parent>
      <axis>
        <limit>
          <lower>-1.57</lower>
          <upper>0</upper>
        </limit>
        <xyz>0 1 0</xyz>
      </axis>
    </joint>

    <joint name="left elbow" type="revolute">
      <pose> 0 -0.15 0 0 0 1.57</pose>
      <child>roboy_left_hand</child>
      <parent>roboy_left_upper_arm</parent>
      <axis>
        <limit>
          <lower>0</lower>
          <upper>1.57</upper>
        </limit>
        <xyz>0 1 0</xyz>
      </axis>
    </joint>

    <joint name="fixed to world" type="revolute">
      <parent>world</parent>
      <child>roboy_pelvis</child>
      <axis>
        <limit>
          <lower>0</lower>
          <upper>0</upper>
        </limit>
        <xyz>0 0 1</xyz>
      </axis>
    </joint>

    <joint name="fixed_box" type="revolute">
      <parent>world</parent>
      <child>box</child>
      <axis>
        <limit>
          <lower>0</lower>
          <upper>0</upper>
        </limit>
        <xyz>0 0 1</xyz>
      </axis>
    </joint>  

    <joint name="right shoulder" type="universal">
      <pose> 0 0 0 0 0 0</pose>
      <child>roboy_right_upper_arm</child>
      <parent>roboy_torso</parent>
      <axis>
        <limit>
          <lower>0</lower>
          <upper>0.79</upper>
        </limit>
        <xyz>0 0 1</xyz>
      </axis>

      <axis2>
        <limit>
          <lower>0</lower>
          <upper>0.79</upper>
        </limit>
        <xyz>1 0 0</xyz>
      </axis2>
    </joint>

    <joint name="left shoulder" type="universal">
      <pose> 0 0 0 0 0 0</pose>
      <child>roboy_left_upper_arm</child>
      <parent>roboy_torso</parent>
      <axis>
        <limit>
          <lower>0</lower>
          <upper>0.79</upper>
        </limit>
        <xyz>0 0 1</xyz>
      </axis>

      <axis2>
        <limit>
          <lower>-0.79</lower>
          <upper>0</upper>
        </limit>
        <xyz>1 0 0</xyz>
      </axis2>
    </joint>

    <joint name="spine" type="fixed">
      <pose> 0 0 0 0 0 0</pose>
      <child>roboy_torso</child>
      <parent>roboy_pelvis</parent>
      <axis>
        <limit>
          <lower>-0.5</lower>
          <upper>0.5</upper>
        </limit>
        <xyz>0 0 1</xyz>
      </axis>

      <axis2>
        <limit>
          <lower>-0.5</lower>
          <upper>0.5</upper>
        </limit>
        <xyz>1 0 0</xyz>
      </axis2>
    </joint>

    <joint name="neck" type="revolute">
      <parent>roboy_torso</parent>
      <child>roboy_head</child>
      <axis>
        <limit>
          <lower>-0.7</lower>
          <upper>0.7</upper>
        </limit>
        <xyz>0 1 0</xyz>
      </axis>
    </joint> 

    <joint name="fixed right thigh" type="revolute">
      <parent>roboy_pelvis</parent>
      <child>roboy_right_thigh</child>
      <axis>
        <limit>
          <lower>0</lower>
          <upper>0</upper>
        </limit>
        <xyz>0 0 1</xyz>
      </axis>
    </joint> 

    <joint name="fixed left thigh" type="revolute">
      <parent>roboy_pelvis</parent>
      <child>roboy_left_thigh</child>
      <axis>
        <limit>
          <lower>0</lower>
          <upper>0</upper>
        </limit>
        <xyz>0 0 1</xyz>
      </axis>
    </joint> 

    <joint name="right ḱnee" type="revolute">
      <pose> 0 -0.25 0 0 0 0</pose>
      <child>roboy_right_shin</child>
      <parent>roboy_right_thigh</parent>
      <axis>
        <limit>
          <lower>-1.57</lower>
          <upper>0</upper>
        </limit>
        <xyz>1 0 0</xyz>
      </axis>
    </joint>

    <joint name="left ḱnee" type="revolute">
      <pose> 0 -0.25 0 0 0 0</pose>
      <child>roboy_left_shin</child>
      <parent>roboy_left_thigh</parent>
      <axis>
        <limit>
          <lower>0</lower>
          <upper>1.57</upper>
        </limit>
        <xyz>1 0 0</xyz>
      </axis>
    </joint>

    <joint name="right ankle" type="revolute">
      <pose> 0 0 0 0 0 0</pose>
      <child>roboy_right_foot</child>
      <parent>roboy_right_shin</parent>
      <axis>
        <limit>
          <lower>-0.7</lower>
          <upper>0</upper>
        </limit>
        <xyz>1 0 0</xyz>
      </axis>
    </joint>

    <joint name="left ankle" type="revolute">
      <pose> 0 0 0 0 0 0</pose>
      <child>roboy_left_foot</child>
      <parent>roboy_left_shin</parent>
      <axis>
        <limit>
          <lower>-0.7</lower>
          <upper>0</upper>
        </limit>
        <xyz>1 0 0</xyz>
      </axis>
    </joint>

    <plugin name='muscle_plugin' filename='libmuscle_plugin.so'>
        <motor>
          <bemf_constant>0.001488</bemf_constant> <!--V/rpm-->
          <torque_constant>14.2</torque_constant> <!--mNm/A-->
          <inductance>0.118</inductance> <!--mH-->
          <resistance>0.797</resistance> <!--Ohm-->
          <inertiaMoment>4.09</inertiaMoment> <!--gcm^2-->
        </motor>
        <gear>
          <ratio>53</ratio>
          <efficiency>0.59</efficiency>
          <inertiaMoment>0.4</inertiaMoment> <!--gcm^2-->
        </gear>
        <spindle>
          <radius>0.005</radius> <!--m-->
        </spindle>
        <SEE>
          <stiffness>1.0</stiffness>
          <!-- <length>0.5</length> -->
          <length0>0.1</length0>
        </SEE>
      </plugin>
      
  </model>

  <physics name='default_physics' default='0' type='ode'>
      <max_step_size>0.001</max_step_size>
      <real_time_factor>0</real_time_factor>
      <real_time_update_rate>0</real_time_update_rate>
      <gravity>0 0 -9.8</gravity>
      <magnetic_field>6e-06 2.3e-05 -4.2e-05</magnetic_field>
    </physics>
    <scene>
      <ambient>0.4 0.4 0.4 1</ambient>
      <background>0.7 0.7 0.7 1</background>
      <shadows>1</shadows>
    </scene>
    <spherical_coordinates>
      <surface_model>EARTH_WGS84</surface_model>
      <latitude_deg>0</latitude_deg>
      <longitude_deg>0</longitude_deg>
      <elevation>0</elevation>
      <heading_deg>0</heading_deg>
    </spherical_coordinates>
    <light name='user_point_light_0' type='point'>
      <pose frame=''>0 -0 1 0 -0 0</pose>
      <diffuse>0.5 0.5 0.5 1</diffuse>
      <specular>0.1 0.1 0.1 1</specular>
      <attenuation>
        <range>20</range>
        <constant>0.5</constant>
        <linear>0.01</linear>
        <quadratic>0.001</quadratic>
      </attenuation>
      <cast_shadows>0</cast_shadows>
      <direction>0 0 -1</direction>
    </light>
    <model name='RoboCup 3D Simulation Field'>
      <static>1</static>
      <link name='field'>
        <pose frame=''>0 0 0.01 0 -0 0</pose>
        <collision name='collision'>
          <geometry>
            <plane>
              <normal>0 0 1</normal>
              <size>30 20</size>
            </plane>
          </geometry>
          <surface>
            <friction>
              <ode>
                <mu>100</mu>
                <mu2>50</mu2>
              </ode>
            </friction>
            <contact>
              <ode/>
            </contact>
            <bounce/>
          </surface>
          <max_contacts>10</max_contacts>
        </collision>
        <visual name='base1'>
          <pose frame=''>0 11 0.001 0 -0 0</pose>
          <cast_shadows>0</cast_shadows>
          <geometry>
            <plane>
              <normal>0 0 1</normal>
              <size>34 2</size>
            </plane>
          </geometry>
          <material>
            <script>
              <uri>model://robocup_3Dsim_field/materials/scripts/</uri>
              <uri>model://robocup_3Dsim_field/materials/textures/</uri>
              <name>RoboCup/FieldBorder</name>
            </script>
          </material>
        </visual>
        <visual name='base2'>
          <pose frame=''>0 -11 0.001 0 -0 0</pose>
          <cast_shadows>0</cast_shadows>
          <geometry>
            <plane>
              <normal>0 0 1</normal>
              <size>34 2</size>
            </plane>
          </geometry>
          <material>
            <script>
              <uri>model://robocup_3Dsim_field/materials/scripts/</uri>
              <uri>model://robocup_3Dsim_field/materials/textures/</uri>
              <name>RoboCup/FieldBorder</name>
            </script>
          </material>
        </visual>
        <visual name='base3'>
          <pose frame=''>16 0 0.001 0 -0 0</pose>
          <cast_shadows>0</cast_shadows>
          <geometry>
            <plane>
              <normal>0 0 1</normal>
              <size>2 20</size>
            </plane>
          </geometry>
          <material>
            <script>
              <uri>model://robocup_3Dsim_field/materials/scripts/</uri>
              <uri>model://robocup_3Dsim_field/materials/textures/</uri>
              <name>RoboCup/FieldBorder</name>
            </script>
          </material>
        </visual>
        <visual name='base4'>
          <pose frame=''>-16 0 0.001 0 -0 0</pose>
          <cast_shadows>0</cast_shadows>
          <geometry>
            <plane>
              <normal>0 0 1</normal>
              <size>2 20</size>
            </plane>
          </geometry>
          <material>
            <script>
              <uri>model://robocup_3Dsim_field/materials/scripts/</uri>
              <uri>model://robocup_3Dsim_field/materials/textures/</uri>
              <name>RoboCup/FieldBorder</name>
            </script>
          </material>
        </visual>
        <visual name='carpet'>
          <cast_shadows>0</cast_shadows>
          <geometry>
            <plane>
              <normal>0 0 1</normal>
              <size>30 20</size>
            </plane>
          </geometry>
          <material>
            <script>
              <uri>model://robocup_3Dsim_field/materials/scripts/</uri>
              <uri>model://robocup_3Dsim_field/materials/textures/</uri>
              <name>RoboCup/Grass</name>
            </script>
          </material>
        </visual>
        <self_collide>0</self_collide>
        <kinematic>0</kinematic>
        <gravity>1</gravity>
      </link>
      <pose frame=''>0 0 0 0 -0 0</pose>
    </model>
    <state world_name='default'>
      <sim_time>0 501000000</sim_time>
      <real_time>12 825593930</real_time>
      <wall_time>1454404910 619713794</wall_time>
      <iterations>501</iterations>
    </state>
    <gui fullscreen='0'>
      <camera name='user_camera'>
        <pose frame=''>5 -5 2 0 0.275643 2.35619</pose>
        <view_controller>orbit</view_controller>
        <projection_type>perspective</projection_type>
      </camera>
    </gui>
  </world>
</sdf>
