<robot
  name="legs">
  <link
    name="hip">
    <inertial>
      <origin
        xyz="-0.037226 -0.041402 -0.034865"
        rpy="0 0 0" />
      <mass
        value="0.64558" />
      <inertia
        ixx="0.0017773"
        ixy="-0.00040131"
        ixz="-0.00040809"
        iyy="0.0039051"
        iyz="-0.00011815"
        izz="0.0035628" />
    </inertial>
    <visual>
      <origin
        xyz="0 0 0"
        rpy="0 0 0" />
      <geometry>
        <mesh
          filename="package://legs/meshes/hip.STL" />
      </geometry>
      <material
        name="">
        <color
          rgba="1 1 1 1" />
      </material>
    </visual>
    <collision>
      <origin
        xyz="0 0 0"
        rpy="0 0 0" />
      <geometry>
        <mesh
          filename="package://legs/meshes/hip.STL" />
      </geometry>
    </collision>
  </link>
  <link
    name="leg_left">
    <inertial>
      <origin
        xyz="0.079186 -0.30308 -0.0019967"
        rpy="0 0 0" />
      <mass
        value="0.36512" />
      <inertia
        ixx="0.030919"
        ixy="8.21E-05"
        ixz="-4.2603E-08"
        iyy="0.00024125"
        iyz="-4.6884E-07"
        izz="0.030921" />
    </inertial>
    <visual>
      <origin
        xyz="0 0 0"
        rpy="0 0 0" />
      <geometry>
        <mesh
          filename="package://legs/meshes/leg_left.STL" />
      </geometry>
      <material
        name="">
        <color
          rgba="1 1 1 1" />
      </material>
    </visual>
    <collision>
      <origin
        xyz="0 0 0"
        rpy="0 0 0" />
      <geometry>
        <mesh
          filename="package://legs/meshes/leg_left.STL" />
      </geometry>
    </collision>
  </link>
  <joint
    name="groin_left"
    type="continuous">
    <origin
      xyz="-0.122266658666271 0 -0.0549999999999983"
      rpy="1.6153920227017 -0.0662050328528786 3.13864040161774" />
    <parent
      link="hip" />
    <child
      link="leg_left" />
    <axis
      xyz="0.997804898834137 -0.0662222308790483 0" />
  </joint>
  <link
    name="foot_left">
    <inertial>
      <origin
        xyz="0.010845 -0.027975 -0.036267"
        rpy="0 0 0" />
      <mass
        value="0.28652" />
      <inertia
        ixx="0.0012083"
        ixy="-3.0637E-06"
        ixz="-4.0244E-05"
        iyy="0.0010853"
        iyz="0.00012925"
        izz="0.00034257" />
    </inertial>
    <visual>
      <origin
        xyz="0 0 0"
        rpy="0 0 0" />
      <geometry>
        <mesh
          filename="package://legs/meshes/foot_left.STL" />
      </geometry>
      <material
        name="">
        <color
          rgba="1 1 1 1" />
      </material>
    </visual>
    <collision>
      <origin
        xyz="0 0 0"
        rpy="0 0 0" />
      <geometry>
        <mesh
          filename="package://legs/meshes/foot_left.STL" />
      </geometry>
    </collision>
  </link>
  <joint
    name="ankle_left"
    type="fixed">
    <origin
      xyz="0.0860660014372935 -0.737498238028814 -0.00916987813484013"
      rpy="2.98844408656729 3.67058813899313E-14 3.14159265358979" />
    <parent
      link="leg_left" />
    <child
      link="foot_left" />
    <axis
      xyz="0 0 0" />
  </joint>
  <link
    name="leg_right">
    <inertial>
      <origin
        xyz="0.11371 -0.28784 -3.5038E-06"
        rpy="0 0 0" />
      <mass
        value="0.36512" />
      <inertia
        ixx="0.030919"
        ixy="0.00036566"
        ixz="-3.8552E-08"
        iyy="0.00024439"
        iyz="4.424E-07"
        izz="0.030924" />
    </inertial>
    <visual>
      <origin
        xyz="0 0 0"
        rpy="0 0 0" />
      <geometry>
        <mesh
          filename="package://legs/meshes/leg_right.STL" />
      </geometry>
      <material
        name="">
        <color
          rgba="1 1 1 1" />
      </material>
    </visual>
    <collision>
      <origin
        xyz="0 0 0"
        rpy="0 0 0" />
      <geometry>
        <mesh
          filename="package://legs/meshes/leg_right.STL" />
      </geometry>
    </collision>
  </link>
  <joint
    name="groin_right"
    type="continuous">
    <origin
      xyz="0.0853966692069178 0 -0.0550000000000006"
      rpy="1.35953656152169 0.0883051103523315 -0.0189110384553061" />
    <parent
      link="hip" />
    <child
      link="leg_right" />
    <axis
      xyz="-0.995925524993319 -0.0901795357427751 0" />
  </joint>
  <link
    name="foot_right">
    <inertial>
      <origin
        xyz="0.0074462 -0.0082455 -0.041287"
        rpy="0 0 0" />
      <mass
        value="0.13765" />
      <inertia
        ixx="0.0007053"
        ixy="2.0382E-06"
        ixz="2.9422E-05"
        iyy="0.00062632"
        iyz="0.00016082"
        izz="0.00014593" />
    </inertial>
    <visual>
      <origin
        xyz="0 0 0"
        rpy="0 0 0" />
      <geometry>
        <mesh
          filename="package://legs/meshes/foot_right.STL" />
      </geometry>
      <material
        name="">
        <color
          rgba="1 1 1 1" />
      </material>
    </visual>
    <collision>
      <origin
        xyz="0 0 0"
        rpy="0 0 0" />
      <geometry>
        <mesh
          filename="package://legs/meshes/foot_right.STL" />
      </geometry>
    </collision>
  </link>
  <joint
    name="ankle_right"
    type="fixed">
    <origin
      xyz="0.102642494098596 -0.72112746560134 0.0124280566689877"
      rpy="-0.267609453545969 -6.89379109353183E-15 7.38124839028132E-16" />
    <parent
      link="leg_right" />
    <child
      link="foot_right" />
    <axis
      xyz="0 0 0" />
  </joint>
</robot>