<sdf version='1.5'>
  <model name='legs'>
    <link name='hip'>
      <pose frame=''>0 0 0 0 -0 0</pose>
      <inertial>
        <pose frame=''>-0.037226 -0.041402 -0.034865 0 -0 0</pose>
        <mass>0.64558</mass>
        <inertia>
          <ixx>0.0017773</ixx>
          <ixy>-0.00040131</ixy>
          <ixz>-0.00040809</ixz>
          <iyy>0.0039051</iyy>
          <iyz>-0.00011815</iyz>
          <izz>0.0035628</izz>
        </inertia>
      </inertial>
      <collision name='hip_collision'>
        <pose frame=''>0 0 0 0 -0 0</pose>
        <geometry>
          <mesh>
            <scale>1 1 1</scale>
            <uri>model://legs/dae/hip.dae</uri>
          </mesh>
        </geometry>
      </collision>
      <visual name='hip_visual'>
        <pose frame=''>0 0 0 0 -0 0</pose>
        <geometry>
          <mesh>
            <scale>1 1 1</scale>
            <uri>model://legs/dae/hip.dae</uri>
          </mesh>
        </geometry>
      </visual>
    </link>
    <link name='leg_left'>
      <pose frame=''>-0.122267 0 -0.055 1.61539 -0.066205 3.13864</pose>
      <inertial>
        <pose frame=''>0.0774426 -0.508679 0.00873252 0 -0 0</pose>
        <mass>0.65164</mass>
        <inertia>
          <ixx>0.0673246</ixx>
          <ixy>-0.000206378</ixy>
          <ixz>-2.38155e-05</ixz>
          <iyy>0.00144635</iyy>
          <iyz>0.00182007</iyz>
          <izz>0.0663462</izz>
        </inertia>
      </inertial>
      <collision name='leg_left_collision'>
        <pose frame=''>0 0 0 0 -0 0</pose>
        <geometry>
          <mesh>
            <scale>1 1 1</scale>
            <uri>model://legs/dae/leg_left.dae</uri>
          </mesh>
        </geometry>
      </collision>
      <collision name='leg_left_collision_leg_left_1'>
        <pose frame=''>0.086066 -0.737498 -0.00916988 2.98844 3.67059e-14 3.14159</pose>
        <geometry>
          <mesh>
            <scale>1 1 1</scale>
            <uri>model://legs/dae/foot_left.dae</uri>
          </mesh>
        </geometry>
      </collision>
      <visual name='leg_left_visual'>
        <pose frame=''>0 0 0 0 -0 0</pose>
        <geometry>
          <mesh>
            <scale>1 1 1</scale>
            <uri>model://legs/dae/leg_left.dae</uri>
          </mesh>
        </geometry>
      </visual>
      <visual name='leg_left_visual_leg_left_1'>
        <pose frame=''>0.086066 -0.737498 -0.00916988 2.98844 3.67059e-14 3.14159</pose>
        <geometry>
          <mesh>
            <scale>1 1 1</scale>
            <uri>model://legs/dae/foot_left.dae</uri>
          </mesh>
        </geometry>
      </visual>
    </link>
    <joint name='groin_left' type='revolute'>
      <child>leg_left</child>
      <parent>hip</parent>
      <axis>
        <xyz>-1 5.89806e-17 8.67362e-17</xyz>
        <limit>
          <lower>-1e+16</lower>
          <upper>1e+16</upper>
        </limit>
        <dynamics>
          <spring_reference>0</spring_reference>
          <spring_stiffness>0</spring_stiffness>
        </dynamics>
        <use_parent_model_frame>1</use_parent_model_frame>
      </axis>
    </joint>
    <link name='leg_right'>
      <pose frame=''>0.0853967 0 -0.055 1.35954 0.0883051 -0.018911</pose>
      <inertial>
        <pose frame=''>0.112719 -0.411633 -0.00690436 0 -0 0</pose>
        <mass>0.50277</mass>
        <inertia>
          <ixx>0.052125</ixx>
          <ixy>0.000211725</ixy>
          <ixz>1.86729e-05</ixz>
          <iyy>0.000983963</iyy>
          <iyz>-0.00112301</iyz>
          <izz>0.05146</izz>
        </inertia>
      </inertial>
      <collision name='leg_right_collision'>
        <pose frame=''>0 0 0 0 -0 0</pose>
        <geometry>
          <mesh>
            <scale>1 1 1</scale>
            <uri>model://legs/dae/leg_right.dae</uri>
          </mesh>
        </geometry>
      </collision>
      <collision name='leg_right_collision_leg_right_1'>
        <pose frame=''>0.102642 -0.721127 0.0124281 -0.267609 -6.89379e-15 7.38125e-16</pose>
        <geometry>
          <mesh>
            <scale>1 1 1</scale>
            <uri>model://legs/dae/foot_right.dae</uri>
          </mesh>
        </geometry>
      </collision>
      <visual name='leg_right_visual'>
        <pose frame=''>0 0 0 0 -0 0</pose>
        <geometry>
          <mesh>
            <scale>1 1 1</scale>
            <uri>model://legs/dae/leg_right.dae</uri>
          </mesh>
        </geometry>
      </visual>
      <visual name='leg_right_visual_leg_right_1'>
        <pose frame=''>0.102642 -0.721127 0.0124281 -0.267609 -6.89379e-15 7.38125e-16</pose>
        <geometry>
          <mesh>
            <scale>1 1 1</scale>
            <uri>model://legs/dae/foot_right.dae</uri>
          </mesh>
        </geometry>
      </visual>
    </link>
    <joint name='groin_right' type='revolute'>
      <child>leg_right</child>
      <parent>hip</parent>
      <axis>
        <xyz>-1 1.31145e-15 -1.94289e-16</xyz>
        <limit>
          <lower>-1e+16</lower>
          <upper>1e+16</upper>
        </limit>
        <dynamics>
          <spring_reference>0</spring_reference>
          <spring_stiffness>0</spring_stiffness>
        </dynamics>
        <use_parent_model_frame>1</use_parent_model_frame>
      </axis>
    </joint>
  </model>
</sdf>
