<sdf version='1.5'>
  <world name='default'>
    <model name='arm'>
      <pose frame=''>0 0 0 0 -0 0</pose>
      <static>0</static>
      <static>1</static>
      <link name='arm_holder'>
        <gravity>0</gravity>
        <pose frame=''>0 0.31 0.3 0 -0 0</pose>
        <inertial>
          <mass>5</mass>
          <pose frame=''>0 0 0 0 -0 0</pose>
          <inertia>
            <ixx>1</ixx>
            <ixy>0</ixy>
            <ixz>0</ixz>
            <iyy>1</iyy>
            <iyz>0</iyz>
            <izz>1</izz>
          </inertia>
        </inertial>
        <collision name='collision'>
          <geometry>
            <box>
              <size>0.1 0.1 0.6</size>
            </box>
          </geometry>
          <max_contacts>10</max_contacts>
          <surface>
            <contact>
              <ode/>
            </contact>
            <bounce/>
            <friction>
              <ode/>
            </friction>
          </surface>
        </collision>
        <visual name='visual'>
          <geometry>
            <box>
              <size>0.1 0.1 0.6</size>
            </box>
          </geometry>
        </visual>
        <self_collide>0</self_collide>
        <kinematic>0</kinematic>
      </link>
      <link name='hand'>
        <gravity>1</gravity>
        <pose frame=''>0.14 0.197 0.335 0 0 -1.5707</pose>
        <inertial>
          <mass>0.2</mass>
          <pose frame=''>0 0 0 0 -0 0</pose>
          <inertia>
            <ixx>1</ixx>
            <ixy>0</ixy>
            <ixz>0</ixz>
            <iyy>1</iyy>
            <iyz>0</iyz>
            <izz>1</izz>
          </inertia>
        </inertial>
        <self_collide>0</self_collide>
        <kinematic>0</kinematic>
        <visual name='visual'>
          <geometry>
            <mesh>
              <scale>1 1 1</scale>
              <uri>model://arm/dae/p-handflaeche-teil-2-v01.dae</uri>
            </mesh>
          </geometry>
          <material>
            <shader type='pixel'>
              <normal_map>__default__</normal_map>
            </shader>
          </material>
          <pose frame=''>0 0 0 0 -0 0</pose>
          <cast_shadows>1</cast_shadows>
          <transparency>0</transparency>
        </visual>
        <collision name='collision'>
          <laser_retro>0</laser_retro>
          <max_contacts>10</max_contacts>
          <pose frame=''>0 0 0 0 -0 0</pose>
          <geometry>
            <mesh>
              <uri>model://arm/dae/p-handflaeche-teil-2-v01.dae</uri>
            </mesh>
          </geometry>
          <surface>
            <contact>
              <ode/>
            </contact>
            <bounce/>
            <friction>
              <ode/>
            </friction>
          </surface>
        </collision>
      </link>
      <link name='upper_arm'>
        <gravity>1</gravity>
        <pose frame=''>-0 0.22 0.55 1.57 -0 1.5707</pose>
        <inertial>
          <mass>0.3</mass>
          <pose frame=''>0 0 0 0 -0 0</pose>
          <inertia>
            <ixx>1</ixx>
            <ixy>0</ixy>
            <ixz>0</ixz>
            <iyy>1</iyy>
            <iyz>0</iyz>
            <izz>1</izz>
          </inertia>
        </inertial>
        <self_collide>0</self_collide>
        <kinematic>0</kinematic>
        <visual name='visual'>
          <geometry>
            <mesh>
              <scale>1 1 1</scale>
              <uri>model://arm/dae/p-oberarm-1-v02.dae</uri>
            </mesh>
          </geometry>
          <material>
            <shader type='pixel'>
              <normal_map>__default__</normal_map>
            </shader>
          </material>
          <pose frame=''>0 0 0 0 -0 0</pose>
          <cast_shadows>1</cast_shadows>
          <transparency>0</transparency>
        </visual>
        <collision name='collision'>
          <laser_retro>0</laser_retro>
          <max_contacts>10</max_contacts>
          <pose frame=''>0 0 0 0 -0 0</pose>
          <geometry>
            <mesh>
              <uri>model://arm/dae/p-oberarm-1-v02.dae</uri>
            </mesh>
          </geometry>
          <surface>
            <contact>
              <ode/>
            </contact>
            <bounce/>
            <friction>
              <ode/>
            </friction>
          </surface>
        </collision>
      </link>
      <joint name='elbow' type='revolute'>
        <pose frame=''>0 -0.15 0 0 -0 1.57</pose>
        <child>hand</child>
        <parent>upper_arm</parent>
        <axis>
          <limit>
            <lower>-0.7</lower>
            <upper>2</upper>
          </limit>
          <xyz>0 1 0</xyz>
          <use_parent_model_frame>1</use_parent_model_frame>
          <dynamics>
            <spring_reference>0</spring_reference>
            <spring_stiffness>0</spring_stiffness>
          </dynamics>
        </axis>
      </joint>
      <joint name='arm_holder_upper_arm' type='fixed'>
        <pose frame=''>0 -0.02 0 0 -0 0</pose>
        <child>upper_arm</child>
        <parent>arm_holder</parent>
      </joint>
      <joint name='armholder_ground' type='revolute'>
        <pose frame=''>0 0 -0.3 0 -0 0</pose>
        <parent>world</parent>
        <child>arm_holder</child>
      </joint>
      <plugin name='muscle_plugin' filename='libmuscle_plugin.so'>
        <motor>
          <bemf_constant>0.001488</bemf_constant> <!--V/rpm-->
          <torque_constant>14.2</torque_constant> <!--mNm/A-->
          <inductance>0.118</inductance> <!--mH-->
          <resistance>0.797</resistance> <!--Ohm-->
          <inertiaMoment>4.09</inertiaMoment> <!--gcm^2-->
        </motor>
        <gear>
          <ratio>53</ratio>
          <efficiency>0.59</efficiency>
          <inertiaMoment>0.4</inertiaMoment> <!--gcm^2-->
        </gear>
        <spindle>
          <radius>0.005</radius> <!--m-->
        </spindle>
        <SEE>
          <stiffness>1.0</stiffness>
          <!-- <length>0.5</length> -->
          <length0>0.1</length0>
        </SEE>
      </plugin>
    </model>
    <physics name='default_physics' default='0' type='ode'>
      <max_step_size>0.001</max_step_size>
      <real_time_factor>1</real_time_factor>
      <real_time_update_rate>1000</real_time_update_rate>
      <gravity>0 0 -9.8</gravity>
      <magnetic_field>6e-06 2.3e-05 -4.2e-05</magnetic_field>
    </physics>
    <scene>
      <ambient>0.4 0.4 0.4 1</ambient>
      <background>0.7 0.7 0.7 1</background>
      <shadows>1</shadows>
    </scene>
    <spherical_coordinates>
      <surface_model>EARTH_WGS84</surface_model>
      <latitude_deg>0</latitude_deg>
      <longitude_deg>0</longitude_deg>
      <elevation>0</elevation>
      <heading_deg>0</heading_deg>
    </spherical_coordinates>
    <light name='user_point_light_0' type='point'>
      <pose frame=''>0 -0 1 0 -0 0</pose>
      <diffuse>0.5 0.5 0.5 1</diffuse>
      <specular>0.1 0.1 0.1 1</specular>
      <attenuation>
        <range>20</range>
        <constant>0.5</constant>
        <linear>0.01</linear>
        <quadratic>0.001</quadratic>
      </attenuation>
      <cast_shadows>0</cast_shadows>
      <direction>0 0 -1</direction>
    </light>
    <model name='RoboCup 3D Simulation Field'>
      <static>1</static>
      <link name='field'>
        <pose frame=''>0 0 0.01 0 -0 0</pose>
        <collision name='collision'>
          <geometry>
            <plane>
              <normal>0 0 1</normal>
              <size>30 20</size>
            </plane>
          </geometry>
          <surface>
            <friction>
              <ode>
                <mu>100</mu>
                <mu2>50</mu2>
              </ode>
            </friction>
            <contact>
              <ode/>
            </contact>
            <bounce/>
          </surface>
          <max_contacts>10</max_contacts>
        </collision>
        <visual name='base1'>
          <pose frame=''>0 11 0.001 0 -0 0</pose>
          <cast_shadows>0</cast_shadows>
          <geometry>
            <plane>
              <normal>0 0 1</normal>
              <size>34 2</size>
            </plane>
          </geometry>
          <material>
            <script>
              <uri>model://robocup_3Dsim_field/materials/scripts/</uri>
              <uri>model://robocup_3Dsim_field/materials/textures/</uri>
              <name>RoboCup/FieldBorder</name>
            </script>
          </material>
        </visual>
        <visual name='base2'>
          <pose frame=''>0 -11 0.001 0 -0 0</pose>
          <cast_shadows>0</cast_shadows>
          <geometry>
            <plane>
              <normal>0 0 1</normal>
              <size>34 2</size>
            </plane>
          </geometry>
          <material>
            <script>
              <uri>model://robocup_3Dsim_field/materials/scripts/</uri>
              <uri>model://robocup_3Dsim_field/materials/textures/</uri>
              <name>RoboCup/FieldBorder</name>
            </script>
          </material>
        </visual>
        <visual name='base3'>
          <pose frame=''>16 0 0.001 0 -0 0</pose>
          <cast_shadows>0</cast_shadows>
          <geometry>
            <plane>
              <normal>0 0 1</normal>
              <size>2 20</size>
            </plane>
          </geometry>
          <material>
            <script>
              <uri>model://robocup_3Dsim_field/materials/scripts/</uri>
              <uri>model://robocup_3Dsim_field/materials/textures/</uri>
              <name>RoboCup/FieldBorder</name>
            </script>
          </material>
        </visual>
        <visual name='base4'>
          <pose frame=''>-16 0 0.001 0 -0 0</pose>
          <cast_shadows>0</cast_shadows>
          <geometry>
            <plane>
              <normal>0 0 1</normal>
              <size>2 20</size>
            </plane>
          </geometry>
          <material>
            <script>
              <uri>model://robocup_3Dsim_field/materials/scripts/</uri>
              <uri>model://robocup_3Dsim_field/materials/textures/</uri>
              <name>RoboCup/FieldBorder</name>
            </script>
          </material>
        </visual>
        <visual name='carpet'>
          <cast_shadows>0</cast_shadows>
          <geometry>
            <plane>
              <normal>0 0 1</normal>
              <size>30 20</size>
            </plane>
          </geometry>
          <material>
            <script>
              <uri>model://robocup_3Dsim_field/materials/scripts/</uri>
              <uri>model://robocup_3Dsim_field/materials/textures/</uri>
              <name>RoboCup/Grass</name>
            </script>
          </material>
        </visual>
        <self_collide>0</self_collide>
        <kinematic>0</kinematic>
        <gravity>1</gravity>
      </link>
      <pose frame=''>0 0 0 0 -0 0</pose>
    </model>
    <state world_name='default'>
      <sim_time>0 501000000</sim_time>
      <real_time>12 825593930</real_time>
      <wall_time>1454404910 619713794</wall_time>
      <iterations>501</iterations>
      <model name='RoboCup 3D Simulation Field'>
        <pose frame=''>0 0 0 0 -0 0</pose>
        <link name='field'>
          <pose frame=''>0 0 0.01 0 -0 0</pose>
          <velocity>0 0 0 0 -0 0</velocity>
          <acceleration>0 0 0 0 -0 0</acceleration>
          <wrench>0 0 0 0 -0 0</wrench>
        </link>
      </model>
      <model name='arm'>
        <pose frame=''>0 0 -1.23236 0 -0 0</pose>
        <link name='arm_holder'>
          <pose frame=''>0 0.304797 0.299955 0.017346 -0 0</pose>
          <velocity>0 -0.021018 -0.000364 0.070069 -0 0</velocity>
          <acceleration>-0 -0.05115 -0.002353 0.170609 -0 0</acceleration>
          <wrench>-0 -0.255749 -0.011764 0 -0 0</wrench>
        </link>
        <link name='asphalt_plane::link'>
          <pose frame=''>0 0 -1.23236 0 -0 0</pose>
          <velocity>0 0 -4.9098 0 -0 0</velocity>
          <acceleration>0 0 -9.8 0 -0 0</acceleration>
          <wrench>0 0 -9.8 0 -0 0</wrench>
        </link>
        <link name='hand'>
          <pose frame=''>0.139981 0.191248 0.330579 -0.01607 0.017347 -1.5707</pose>
          <velocity>-3.6e-05 -0.023125 -0.01055 0.070069 0.014865 0.000259</velocity>
          <acceleration>0.059102 -0.118833 3.67035 0.170609 0.514803 -0.422732</acceleration>
          <wrench>0.01182 -0.023767 0.73407 0 -0 0</wrench>
        </link>
        <link name='upper_arm'>
          <pose frame=''>0 0.210474 0.548356 1.57 -0.017346 1.5707</pose>
          <velocity>0 -0.038423 -0.006972 0.070069 -0 0</velocity>
          <acceleration>0 -0.093069 -0.019659 0.170609 -0 0</acceleration>
          <wrench>0 -0.027921 -0.005898 0 -0 0</wrench>
        </link>
      </model>
    </state>
    <gui fullscreen='0'>
      <camera name='user_camera'>
        <pose frame=''>5 -5 2 0 0.275643 2.35619</pose>
        <view_controller>orbit</view_controller>
        <projection_type>perspective</projection_type>
      </camera>
    </gui>
  </world>
</sdf>